Workbook
Name Name: Summary!$C$2:$C$12

Sheet Find Peripheral
A1: Search | B1: PIN | C1: Name
A2: EPWM7 | B2: {=OFFSET(Summary!$B$1,SMALL(IFERROR(IF(FIND($A$2,Summary!$C$1:$C$217)>=1,ROW(Summary!$B$1:$B$217),),9999),ROW(Summary!1:1))-1,)} -> 1 | C2: {=OFFSET(Summary!$C$1,SMALL(IFERROR(IF(FIND($A$2,Summary!$C$1:$C$217)>=1,ROW(Summary!$C$1:$C$217),),9999),ROW(Summary!1:1))-1,)} -> GPIO28/ SCIA_RX/ EPWM7_A/ OUTPUTXBAR5/ EQEP1_A/ SD1_D3/ EQEP2_STROBE/ LINA_TX/ SPIB_CLK/ ERRORSTS
B3: {=OFFSET(Summary!$B$1,SMALL(IFERROR(IF(FIND($A$2,Summary!$C$1:$C$217)>=1,ROW(Summary!$B$1:$B$217),),9999),ROW(Summary!2:2))-1,)} -> 50 | C3: {=OFFSET(Summary!$C$1,SMALL(IFERROR(IF(FIND($A$2,Summary!$C$1:$C$217)>=1,ROW(Summary!$C$1:$C$217),),9999),ROW(Summary!2:2))-1,)} -> GPIO13/ EPWM7_B/ CANB_RX/ EQEP1_INDEX/ SCIB_RX/ PMBUSA_ALERT/ FSIRXA_CLK
B4: {=OFFSET(Summary!$B$1,SMALL(IFERROR(IF(FIND($A$2,Summary!$C$1:$C$217)>=1,ROW(Summary!$B$1:$B$217),),9999),ROW(Summary!3:3))-1,)} -> 51 | C4: {=OFFSET(Summary!$C$1,SMALL(IFERROR(IF(FIND($A$2,Summary!$C$1:$C$217)>=1,ROW(Summary!$C$1:$C$217),),9999),ROW(Summary!3:3))-1,)} -> GPIO12/ EPWM7_A/ CANB_TX/ EQEP1_STROBE/ SCIB_TX/ PMBUSA_CTL/ FSIRXA_D0
B5: {=OFFSET(Summary!$B$1,SMALL(IFERROR(IF(FIND($A$2,Summary!$C$1:$C$217)>=1,ROW(Summary!$B$1:$B$217),),9999),ROW(Summary!4:4))-1,)} -> 100 | C5: {=OFFSET(Summary!$C$1,SMALL(IFERROR(IF(FIND($A$2,Summary!$C$1:$C$217)>=1,ROW(Summary!$C$1:$C$217),),9999),ROW(Summary!4:4))-1,)} -> GPIO29/ SCIA_TX/ EPWM7_B/ OUTPUTXBAR6/ EQEP1_B/ SD1_C3/ EQEP2_INDEX/ LINA_RX/ SPIB_STE/ ERRORSTS
B6: {=OFFSET(Summary!$B$1,SMALL(IFERROR(IF(FIND($A$2,Summary!$C$1:$C$217)>=1,ROW(Summary!$B$1:$B$217),),9999),ROW(Summary!5:5))-1,)} -> 0 | C6: {=OFFSET(Summary!$C$1,SMALL(IFERROR(IF(FIND($A$2,Summary!$C$1:$C$217)>=1,ROW(Summary!$C$1:$C$217),),9999),ROW(Summary!5:5))-1,)} -> 0
B7: {=OFFSET(Summary!$B$1,SMALL(IFERROR(IF(FIND($A$2,Summary!$C$1:$C$217)>=1,ROW(Summary!$B$1:$B$217),),9999),ROW(Summary!6:6))-1,)} -> 0 | C7: {=OFFSET(Summary!$C$1,SMALL(IFERROR(IF(FIND($A$2,Summary!$C$1:$C$217)>=1,ROW(Summary!$C$1:$C$217),),9999),ROW(Summary!6:6))-1,)} -> 0
B8: {=OFFSET(Summary!$B$1,SMALL(IFERROR(IF(FIND($A$2,Summary!$C$1:$C$217)>=1,ROW(Summary!$B$1:$B$217),),9999),ROW(Summary!7:7))-1,)} -> 0 | C8: {=OFFSET(Summary!$C$1,SMALL(IFERROR(IF(FIND($A$2,Summary!$C$1:$C$217)>=1,ROW(Summary!$C$1:$C$217),),9999),ROW(Summary!7:7))-1,)} -> 0
B9: {=OFFSET(Summary!$B$1,SMALL(IFERROR(IF(FIND($A$2,Summary!$C$1:$C$217)>=1,ROW(Summary!$B$1:$B$217),),9999),ROW(Summary!8:8))-1,)} -> 0 | C9: {=OFFSET(Summary!$C$1,SMALL(IFERROR(IF(FIND($A$2,Summary!$C$1:$C$217)>=1,ROW(Summary!$C$1:$C$217),),9999),ROW(Summary!8:8))-1,)} -> 0
B10: {=OFFSET(Summary!$B$1,SMALL(IFERROR(IF(FIND($A$2,Summary!$C$1:$C$217)>=1,ROW(Summary!$B$1:$B$217),),9999),ROW(Summary!9:9))-1,)} -> 0 | C10: {=OFFSET(Summary!$C$1,SMALL(IFERROR(IF(FIND($A$2,Summary!$C$1:$C$217)>=1,ROW(Summary!$C$1:$C$217),),9999),ROW(Summary!9:9))-1,)} -> 0
B11: {=OFFSET(Summary!$B$1,SMALL(IFERROR(IF(FIND($A$2,Summary!$C$1:$C$217)>=1,ROW(Summary!$B$1:$B$217),),9999),ROW(Summary!10:10))-1,)} -> 0 | C11: {=OFFSET(Summary!$C$1,SMALL(IFERROR(IF(FIND($A$2,Summary!$C$1:$C$217)>=1,ROW(Summary!$C$1:$C$217),),9999),ROW(Summary!10:10))-1,)} -> 0
B12: {=OFFSET(Summary!$B$1,SMALL(IFERROR(IF(FIND($A$2,Summary!$C$1:$C$217)>=1,ROW(Summary!$B$1:$B$217),),9999),ROW(Summary!11:11))-1,)} -> 0 | C12: {=OFFSET(Summary!$C$1,SMALL(IFERROR(IF(FIND($A$2,Summary!$C$1:$C$217)>=1,ROW(Summary!$C$1:$C$217),),9999),ROW(Summary!11:11))-1,)} -> 0
B13: {=OFFSET(Summary!$B$1,SMALL(IFERROR(IF(FIND($A$2,Summary!$C$1:$C$217)>=1,ROW(Summary!$B$1:$B$217),),9999),ROW(Summary!12:12))-1,)} -> 0 | C13: {=OFFSET(Summary!$C$1,SMALL(IFERROR(IF(FIND($A$2,Summary!$C$1:$C$217)>=1,ROW(Summary!$C$1:$C$217),),9999),ROW(Summary!12:12))-1,)} -> 0
B14: {=OFFSET(Summary!$B$1,SMALL(IFERROR(IF(FIND($A$2,Summary!$C$1:$C$217)>=1,ROW(Summary!$B$1:$B$217),),9999),ROW(Summary!13:13))-1,)} -> 0 | C14: {=OFFSET(Summary!$C$1,SMALL(IFERROR(IF(FIND($A$2,Summary!$C$1:$C$217)>=1,ROW(Summary!$C$1:$C$217),),9999),ROW(Summary!13:13))-1,)} -> 0
B15: {=OFFSET(Summary!$B$1,SMALL(IFERROR(IF(FIND($A$2,Summary!$C$1:$C$217)>=1,ROW(Summary!$B$1:$B$217),),9999),ROW(Summary!14:14))-1,)} -> 0 | C15: {=OFFSET(Summary!$C$1,SMALL(IFERROR(IF(FIND($A$2,Summary!$C$1:$C$217)>=1,ROW(Summary!$C$1:$C$217),),9999),ROW(Summary!14:14))-1,)} -> 0
B16: {=OFFSET(Summary!$B$1,SMALL(IFERROR(IF(FIND($A$2,Summary!$C$1:$C$217)>=1,ROW(Summary!$B$1:$B$217),),9999),ROW(Summary!15:15))-1,)} -> 0 | C16: {=OFFSET(Summary!$C$1,SMALL(IFERROR(IF(FIND($A$2,Summary!$C$1:$C$217)>=1,ROW(Summary!$C$1:$C$217),),9999),ROW(Summary!15:15))-1,)} -> 0
B17: {=OFFSET(Summary!$B$1,SMALL(IFERROR(IF(FIND($A$2,Summary!$C$1:$C$217)>=1,ROW(Summary!$B$1:$B$217),),9999),ROW(Summary!16:16))-1,)} -> 0 | C17: {=OFFSET(Summary!$C$1,SMALL(IFERROR(IF(FIND($A$2,Summary!$C$1:$C$217)>=1,ROW(Summary!$C$1:$C$217),),9999),ROW(Summary!16:16))-1,)} -> 0
B18: {=OFFSET(Summary!$B$1,SMALL(IFERROR(IF(FIND($A$2,Summary!$C$1:$C$217)>=1,ROW(Summary!$B$1:$B$217),),9999),ROW(Summary!17:17))-1,)} -> 0 | C18: {=OFFSET(Summary!$C$1,SMALL(IFERROR(IF(FIND($A$2,Summary!$C$1:$C$217)>=1,ROW(Summary!$C$1:$C$217),),9999),ROW(Summary!17:17))-1,)} -> 0
B19: {=OFFSET(Summary!$B$1,SMALL(IFERROR(IF(FIND($A$2,Summary!$C$1:$C$217)>=1,ROW(Summary!$B$1:$B$217),),9999),ROW(Summary!18:18))-1,)} -> 0 | C19: {=OFFSET(Summary!$C$1,SMALL(IFERROR(IF(FIND($A$2,Summary!$C$1:$C$217)>=1,ROW(Summary!$C$1:$C$217),),9999),ROW(Summary!18:18))-1,)} -> 0
B20: {=OFFSET(Summary!$B$1,SMALL(IFERROR(IF(FIND($A$2,Summary!$C$1:$C$217)>=1,ROW(Summary!$B$1:$B$217),),9999),ROW(Summary!19:19))-1,)} -> 0 | C20: {=OFFSET(Summary!$C$1,SMALL(IFERROR(IF(FIND($A$2,Summary!$C$1:$C$217)>=1,ROW(Summary!$C$1:$C$217),),9999),ROW(Summary!19:19))-1,)} -> 0
B21: {=OFFSET(Summary!$B$1,SMALL(IFERROR(IF(FIND($A$2,Summary!$C$1:$C$217)>=1,ROW(Summary!$B$1:$B$217),),9999),ROW(Summary!20:20))-1,)} -> 0 | C21: {=OFFSET(Summary!$C$1,SMALL(IFERROR(IF(FIND($A$2,Summary!$C$1:$C$217)>=1,ROW(Summary!$C$1:$C$217),),9999),ROW(Summary!20:20))-1,)} -> 0
B22: {=OFFSET(Summary!$B$1,SMALL(IFERROR(IF(FIND($A$2,Summary!$C$1:$C$217)>=1,ROW(Summary!$B$1:$B$217),),9999),ROW(Summary!21:21))-1,)} -> 0 | C22: {=OFFSET(Summary!$C$1,SMALL(IFERROR(IF(FIND($A$2,Summary!$C$1:$C$217)>=1,ROW(Summary!$C$1:$C$217),),9999),ROW(Summary!21:21))-1,)} -> 0
B23: {=OFFSET(Summary!$B$1,SMALL(IFERROR(IF(FIND($A$2,Summary!$C$1:$C$217)>=1,ROW(Summary!$B$1:$B$217),),9999),ROW(Summary!22:22))-1,)} -> 0 | C23: {=OFFSET(Summary!$C$1,SMALL(IFERROR(IF(FIND($A$2,Summary!$C$1:$C$217)>=1,ROW(Summary!$C$1:$C$217),),9999),ROW(Summary!22:22))-1,)} -> 0
B24: {=OFFSET(Summary!$B$1,SMALL(IFERROR(IF(FIND($A$2,Summary!$C$1:$C$217)>=1,ROW(Summary!$B$1:$B$217),),9999),ROW(Summary!23:23))-1,)} -> 0 | C24: {=OFFSET(Summary!$C$1,SMALL(IFERROR(IF(FIND($A$2,Summary!$C$1:$C$217)>=1,ROW(Summary!$C$1:$C$217),),9999),ROW(Summary!23:23))-1,)} -> 0
B25: {=OFFSET(Summary!$B$1,SMALL(IFERROR(IF(FIND($A$2,Summary!$C$1:$C$217)>=1,ROW(Summary!$B$1:$B$217),),9999),ROW(Summary!24:24))-1,)} -> 0 | C25: {=OFFSET(Summary!$C$1,SMALL(IFERROR(IF(FIND($A$2,Summary!$C$1:$C$217)>=1,ROW(Summary!$C$1:$C$217),),9999),ROW(Summary!24:24))-1,)} -> 0
B26: {=OFFSET(Summary!$B$1,SMALL(IFERROR(IF(FIND($A$2,Summary!$C$1:$C$217)>=1,ROW(Summary!$B$1:$B$217),),9999),ROW(Summary!25:25))-1,)} -> 0 | C26: {=OFFSET(Summary!$C$1,SMALL(IFERROR(IF(FIND($A$2,Summary!$C$1:$C$217)>=1,ROW(Summary!$C$1:$C$217),),9999),ROW(Summary!25:25))-1,)} -> 0
B27: {=OFFSET(Summary!$B$1,SMALL(IFERROR(IF(FIND($A$2,Summary!$C$1:$C$217)>=1,ROW(Summary!$B$1:$B$217),),9999),ROW(Summary!26:26))-1,)} -> 0 | C27: {=OFFSET(Summary!$C$1,SMALL(IFERROR(IF(FIND($A$2,Summary!$C$1:$C$217)>=1,ROW(Summary!$C$1:$C$217),),9999),ROW(Summary!26:26))-1,)} -> 0
B28: {=OFFSET(Summary!$B$1,SMALL(IFERROR(IF(FIND($A$2,Summary!$C$1:$C$217)>=1,ROW(Summary!$B$1:$B$217),),9999),ROW(Summary!27:27))-1,)} -> 0 | C28: {=OFFSET(Summary!$C$1,SMALL(IFERROR(IF(FIND($A$2,Summary!$C$1:$C$217)>=1,ROW(Summary!$C$1:$C$217),),9999),ROW(Summary!27:27))-1,)} -> 0
B29: {=OFFSET(Summary!$B$1,SMALL(IFERROR(IF(FIND($A$2,Summary!$C$1:$C$217)>=1,ROW(Summary!$B$1:$B$217),),9999),ROW(Summary!28:28))-1,)} -> 0 | C29: {=OFFSET(Summary!$C$1,SMALL(IFERROR(IF(FIND($A$2,Summary!$C$1:$C$217)>=1,ROW(Summary!$C$1:$C$217),),9999),ROW(Summary!28:28))-1,)} -> 0
B30: {=OFFSET(Summary!$B$1,SMALL(IFERROR(IF(FIND($A$2,Summary!$C$1:$C$217)>=1,ROW(Summary!$B$1:$B$217),),9999),ROW(Summary!29:29))-1,)} -> 0 | C30: {=OFFSET(Summary!$C$1,SMALL(IFERROR(IF(FIND($A$2,Summary!$C$1:$C$217)>=1,ROW(Summary!$C$1:$C$217),),9999),ROW(Summary!29:29))-1,)} -> 0
B31: {=OFFSET(Summary!$B$1,SMALL(IFERROR(IF(FIND($A$2,Summary!$C$1:$C$217)>=1,ROW(Summary!$B$1:$B$217),),9999),ROW(Summary!30:30))-1,)} -> 0 | C31: {=OFFSET(Summary!$C$1,SMALL(IFERROR(IF(FIND($A$2,Summary!$C$1:$C$217)>=1,ROW(Summary!$C$1:$C$217),),9999),ROW(Summary!30:30))-1,)} -> 0
B32: {=OFFSET(Summary!$B$1,SMALL(IFERROR(IF(FIND($A$2,Summary!$C$1:$C$217)>=1,ROW(Summary!$B$1:$B$217),),9999),ROW(Summary!31:31))-1,)} -> 0 | C32: {=OFFSET(Summary!$C$1,SMALL(IFERROR(IF(FIND($A$2,Summary!$C$1:$C$217)>=1,ROW(Summary!$C$1:$C$217),),9999),ROW(Summary!31:31))-1,)} -> 0
B33: {=OFFSET(Summary!$B$1,SMALL(IFERROR(IF(FIND($A$2,Summary!$C$1:$C$217)>=1,ROW(Summary!$B$1:$B$217),),9999),ROW(Summary!32:32))-1,)} -> 0 | C33: {=OFFSET(Summary!$C$1,SMALL(IFERROR(IF(FIND($A$2,Summary!$C$1:$C$217)>=1,ROW(Summary!$C$1:$C$217),),9999),ROW(Summary!32:32))-1,)} -> 0
B34: {=OFFSET(Summary!$B$1,SMALL(IFERROR(IF(FIND($A$2,Summary!$C$1:$C$217)>=1,ROW(Summary!$B$1:$B$217),),9999),ROW(Summary!33:33))-1,)} -> 0 | C34: {=OFFSET(Summary!$C$1,SMALL(IFERROR(IF(FIND($A$2,Summary!$C$1:$C$217)>=1,ROW(Summary!$C$1:$C$217),),9999),ROW(Summary!33:33))-1,)} -> 0
B35: {=OFFSET(Summary!$B$1,SMALL(IFERROR(IF(FIND($A$2,Summary!$C$1:$C$217)>=1,ROW(Summary!$B$1:$B$217),),9999),ROW(Summary!34:34))-1,)} -> 0 | C35: {=OFFSET(Summary!$C$1,SMALL(IFERROR(IF(FIND($A$2,Summary!$C$1:$C$217)>=1,ROW(Summary!$C$1:$C$217),),9999),ROW(Summary!34:34))-1,)} -> 0
B36: {=OFFSET(Summary!$B$1,SMALL(IFERROR(IF(FIND($A$2,Summary!$C$1:$C$217)>=1,ROW(Summary!$B$1:$B$217),),9999),ROW(Summary!35:35))-1,)} -> 0 | C36: {=OFFSET(Summary!$C$1,SMALL(IFERROR(IF(FIND($A$2,Summary!$C$1:$C$217)>=1,ROW(Summary!$C$1:$C$217),),9999),ROW(Summary!35:35))-1,)} -> 0
B37: {=OFFSET(Summary!$B$1,SMALL(IFERROR(IF(FIND($A$2,Summary!$C$1:$C$217)>=1,ROW(Summary!$B$1:$B$217),),9999),ROW(Summary!36:36))-1,)} -> 0 | C37: {=OFFSET(Summary!$C$1,SMALL(IFERROR(IF(FIND($A$2,Summary!$C$1:$C$217)>=1,ROW(Summary!$C$1:$C$217),),9999),ROW(Summary!36:36))-1,)} -> 0
B38: {=OFFSET(Summary!$B$1,SMALL(IFERROR(IF(FIND($A$2,Summary!$C$1:$C$217)>=1,ROW(Summary!$B$1:$B$217),),9999),ROW(Summary!37:37))-1,)} -> 0 | C38: {=OFFSET(Summary!$C$1,SMALL(IFERROR(IF(FIND($A$2,Summary!$C$1:$C$217)>=1,ROW(Summary!$C$1:$C$217),),9999),ROW(Summary!37:37))-1,)} -> 0
B39: {=OFFSET(Summary!$B$1,SMALL(IFERROR(IF(FIND($A$2,Summary!$C$1:$C$217)>=1,ROW(Summary!$B$1:$B$217),),9999),ROW(Summary!38:38))-1,)} -> 0 | C39: {=OFFSET(Summary!$C$1,SMALL(IFERROR(IF(FIND($A$2,Summary!$C$1:$C$217)>=1,ROW(Summary!$C$1:$C$217),),9999),ROW(Summary!38:38))-1,)} -> 0
B40: {=OFFSET(Summary!$B$1,SMALL(IFERROR(IF(FIND($A$2,Summary!$C$1:$C$217)>=1,ROW(Summary!$B$1:$B$217),),9999),ROW(Summary!39:39))-1,)} -> 0 | C40: {=OFFSET(Summary!$C$1,SMALL(IFERROR(IF(FIND($A$2,Summary!$C$1:$C$217)>=1,ROW(Summary!$C$1:$C$217),),9999),ROW(Summary!39:39))-1,)} -> 0
...

Sheet Summary
B1: PIN | D1: State
B2: 1 | C2: GPIO28/ SCIA_RX/ EPWM7_A/ OUTPUTXBAR5/ EQEP1_A/ SD1_D3/ EQEP2_STROBE/ LINA_TX/ SPIB_CLK/ ERRORSTS | D2: =IF(COUNTIF(Assign!$E:$E,B2)=1,"Occupied",IF(COUNTIF(Assign!$E:$E,B2)=0,"Not Used","Duplicate definitions")) -> Occupied
B3: 2 | C3: XRSn
B4: 3 | C4: VDDIO
B5: 4 | C5: VDD
B6: 5 | C6: VSS
B7: 6 | C7: A6/ PGA5_OF/ CMP5_HP0/ CMP5_LP0/ AIO228 | D7: =IF(COUNTIF(Assign!$E:$E,B7)=1,"Occupied",IF(COUNTIF(Assign!$E:$E,B7)=0,"Not Used","Duplicate definitions")) -> Not Used
B8: 7 | C8: B2/ C6/ PGA3_OF/ CMP3_HP0/ CMP3_LP0/ AIO226 | D8: =IF(COUNTIF(Assign!$E:$E,B8)=1,"Occupied",IF(COUNTIF(Assign!$E:$E,B8)=0,"Not Used","Duplicate definitions")) -> Not Used
B9: 8 | C9: B3/ VDAC/ CMP3_HP3/ CMP3_HN0/ CMP3_LP3/ CMP3_LN0/ AIO242 | D9: =IF(COUNTIF(Assign!$E:$E,B9)=1,"Occupied",IF(COUNTIF(Assign!$E:$E,B9)=0,"Not Used","Duplicate definitions")) -> Not Used
B10: 9 | C10: A2/ B6/ PGA1_OF/ CMP1_HP0/ CMP1_LP0/ AIO224 | D10: =IF(COUNTIF(Assign!$E:$E,B10)=1,"Occupied",IF(COUNTIF(Assign!$E:$E,B10)=0,"Not Used","Duplicate definitions")) -> Not Used
B11: 10 | C11: A3/ CMP1_HP3/ CMP1_HN0/ CMP1_LP3/ CMP1_LN0/ AIO233 | D11: =IF(COUNTIF(Assign!$E:$E,B11)=1,"Occupied",IF(COUNTIF(Assign!$E:$E,B11)=0,"Not Used","Duplicate definitions")) -> Occupied
B12: 11 | C12: VDDA
B13: 12 | C13: VSSA
B14: 13 | C14: PGA5_GND | D14: =IF(COUNTIF(Assign!$E:$E,B14)=1,"Occupied",IF(COUNTIF(Assign!$E:$E,B14)=0,"Not Used","Duplicate definitions")) -> Not Used
B15: 14 | C15: PGA1_GND | D15: =IF(COUNTIF(Assign!$E:$E,B15)=1,"Occupied",IF(COUNTIF(Assign!$E:$E,B15)=0,"Not Used","Duplicate definitions")) -> Not Used
B16: 15 | C16: PGA3_GND | D16: =IF(COUNTIF(Assign!$E:$E,B16)=1,"Occupied",IF(COUNTIF(Assign!$E:$E,B16)=0,"Not Used","Duplicate definitions")) -> Not Used
B17: 16 | C17: PGA5_IN/ CMP5_HP2/ CMP5_LP2 | D17: =IF(COUNTIF(Assign!$E:$E,B17)=1,"Occupied",IF(COUNTIF(Assign!$E:$E,B17)=0,"Not Used","Duplicate definitions")) -> Not Used
B18: 17 | C18: C4/ CMP5_HP1/ CMP5_HN1/ CMP5_LP1/ CMP5_LN1/ AIO239 | D18: =IF(COUNTIF(Assign!$E:$E,B18)=1,"Occupied",IF(COUNTIF(Assign!$E:$E,B18)=0,"Not Used","Duplicate definitions")) -> Occupied
B19: 18 | C19: PGA1_IN/ CMP1_HP2/ CMP1_LP2 | D19: =IF(COUNTIF(Assign!$E:$E,B19)=1,"Occupied",IF(COUNTIF(Assign!$E:$E,B19)=0,"Not Used","Duplicate definitions")) -> Not Used
B20: 19 | C20: C0/ CMP1_HP1/ CMP1_HN1/ CMP1_LP1/ CMP1_LN1/ AIO237 | D20: =IF(COUNTIF(Assign!$E:$E,B20)=1,"Occupied",IF(COUNTIF(Assign!$E:$E,B20)=0,"Not Used","Duplicate definitions")) -> Occupied
B21: 20 | C21: PGA3_IN/ CMP3_HP2/ CMP3_LP2 | D21: =IF(COUNTIF(Assign!$E:$E,B21)=1,"Occupied",IF(COUNTIF(Assign!$E:$E,B21)=0,"Not Used","Duplicate definitions")) -> Not Used
B22: 21 | C22: C2/ CMP3_HP1/ CMP3_HN1/ CMP3_LP1/ CMP3_LN1/ AIO244 | D22: =IF(COUNTIF(Assign!$E:$E,B22)=1,"Occupied",IF(COUNTIF(Assign!$E:$E,B22)=0,"Not Used","Duplicate definitions")) -> Occupied
B23: 22 | C23: A1/ DACB_OUT/ AIO232 | D23: =IF(COUNTIF(Assign!$E:$E,B23)=1,"Occupied",IF(COUNTIF(Assign!$E:$E,B23)=0,"Not Used","Duplicate definitions")) -> Occupied
B24: 23 | C24: A0/ B15/ C15/ DACA_OUT/ AIO231 | D24: =IF(COUNTIF(Assign!$E:$E,B24)=1,"Occupied",IF(COUNTIF(Assign!$E:$E,B24)=0,"Not Used","Duplicate definitions")) -> Occupied
B25: 24 | C25: VREFHIB/ VREFHIC
B26: 25 | C26: VREFHIA
B27: 26 | C27: VREFLOB/ VREFLOC
B28: 27 | C28: VREFLOA
B29: 28 | C29: C5/ CMP6_HP1/ CMP6_HN1/ CMP6_LP1/ CMP6_LN1/ PGA6_IN/ CMP6_HP2/ CMP6_LP2/ AIO240 | D29: =IF(COUNTIF(Assign!$E:$E,B29)=1,"Occupied",IF(COUNTIF(Assign!$E:$E,B29)=0,"Not Used","Duplicate definitions")) -> Occupied
B30: 29 | C30: C1/ CMP2_HP1/ CMP2_HN1/ CMP2_LP1/ CMP2_LN1/ AIO238 | D30: =IF(COUNTIF(Assign!$E:$E,B30)=1,"Occupied",IF(COUNTIF(Assign!$E:$E,B30)=0,"Not Used","Duplicate definitions")) -> Occupied
B31: 30 | C31: PGA2_IN/ CMP2_HP2/ CMP2_LP2 | D31: =IF(COUNTIF(Assign!$E:$E,B31)=1,"Occupied",IF(COUNTIF(Assign!$E:$E,B31)=0,"Not Used","Duplicate definitions")) -> Not Used
B32: 31 | C32: C3/ CMP4_HP1/ CMP4_HN1/ CMP4_LP1/ CMP4_LN1/ PGA4_IN/ CMP4_HP2/ CMP4_LP2/ AIO245 | D32: =IF(COUNTIF(Assign!$E:$E,B32)=1,"Occupied",IF(COUNTIF(Assign!$E:$E,B32)=0,"Not Used","Duplicate definitions")) -> Occupied
B33: 32 | C33: PGA2_GND/ PGA4_GND/ PGA6_GND | D33: =IF(COUNTIF(Assign!$E:$E,B33)=1,"Occupied",IF(COUNTIF(Assign!$E:$E,B33)=0,"Not Used","Duplicate definitions")) -> Not Used
B34: 33 | C34: VSSA
B35: 34 | C35: VDDA
B36: 35 | C36: A5/ CMP2_HP3/ CMP2_HN0/ CMP2_LP3/ CMP2_LN0/ AIO234 | D36: =IF(COUNTIF(Assign!$E:$E,B36)=1,"Occupied",IF(COUNTIF(Assign!$E:$E,B36)=0,"Not Used","Duplicate definitions")) -> Occupied
B37: 36 | C37: A4/ B8/ PGA2_OF/ CMP2_HP0/ CMP2_LP0/ AIO225 | D37: =IF(COUNTIF(Assign!$E:$E,B37)=1,"Occupied",IF(COUNTIF(Assign!$E:$E,B37)=0,"Not Used","Duplicate definitions")) -> Occupied
B38: 37 | C38: A8/ PGA6_OF/ CMP6_HP0/ CMP6_LP0/ AIO229 | D38: =IF(COUNTIF(Assign!$E:$E,B38)=1,"Occupied",IF(COUNTIF(Assign!$E:$E,B38)=0,"Not Used","Duplicate definitions")) -> Occupied
B39: 38 | C39: A9/ CMP6_HP3/ CMP6_HN0/ CMP6_LP3/ CMP6_LN0/ AIO236 | D39: =IF(COUNTIF(Assign!$E:$E,B39)=1,"Occupied",IF(COUNTIF(Assign!$E:$E,B39)=0,"Not Used","Duplicate definitions")) -> Occupied
B40: 39 | C40: B4/ C8/ PGA4_OF/ CMP4_HP0/ CMP4_LP0/ AIO227 | D40: =IF(COUNTIF(Assign!$E:$E,B40)=1,"Occupied",IF(COUNTIF(Assign!$E:$E,B40)=0,"Not Used","Duplicate definitions")) -> Not Used
...

Sheet Assign
B1: PIN | C1: Name | D1: Set | E1: Asserted | F1: Index
B2: JTAG: | D2: =COUNTIF(D3:D4,"v") -> 2 | E2: =IF(D2="v",B2,"") | F2: =IF(B2=E2,F1+1,IF(ISNUMBER(B2),F1,)) -> 0
B3: 63 | C3: GPIO35/ SCIA_RX/ I2CA_SDA/ CANA_RX/ PMBUSA_SCL/ LINA_RX/ EQEP1_A/ PMBUSA_CTL/ TDI | D3: v | E3: =IF(D3="v",B3,"") -> 63 | F3: =IF(B3=E3,F2+1,IF(ISNUMBER(B3),F2,)) -> 1
B4: 61 | C4: GPIO37/ OUTPUTXBAR2/ I2CA_SCL/ SCIA_TX/ CANA_TX/ LINA_TX/ EQEP1_B/ PMBUSA_ALERT/ TDO | D4: v | E4: =IF(D4="v",B4,"") -> 61 | F4: =IF(B4=E4,F3+1,IF(ISNUMBER(B4),F3,)) -> 2
B5: CLOCK: | D5: =COUNTIF(D6:D6,"v") -> 1 | E5: =IF(D5="v",B5,"") | F5: =IF(B5=E5,F4+1,IF(ISNUMBER(B5),F4,)) -> 0
B6: 68 | C6: GPIO18_X2/ SPIA_CLK/ SCIB_TX/ CANA_RX/ EPWM6_A/ I2CA_SCL/ SD1_D2/ EQEP2_A/ PMBUSA_CTL/ XCLKOUT/ X2 | D6: v | E6: =IF(D6="v",B6,"") -> 68 | F6: =IF(B6=E6,F5+1,IF(ISNUMBER(B6),F5,)) -> 1
B7: DEFAULT BOOT MODE SELECT: | D7: =COUNTIF(D8:D9,"v") -> 2 | E7: =IF(D7="v",B7,"") | F7: =IF(B7=E7,F6+1,IF(ISNUMBER(B7),F6,)) -> 0
B8: 56 | C8: GPIO24/ OUTPUTXBAR1/ EQEP2_A/ EPWM8_A/ SPIB_SIMO/ SD1_D1/ PMBUSA_SCL/ SCIA_TX/ ERRORSTS | D8: v | E8: =IF(D8="v",B8,"") -> 56 | F8: =IF(B8=E8,F7+1,IF(ISNUMBER(B8),F7,)) -> 1
B9: 64 | C9: GPIO32/ I2CA_SDA/ SPIB_CLK/ EPWM8_B/ LINA_TX/ SD1_D3/ FSIRXA_D0/ CANA_TX | D9: v | E9: =IF(D9="v",B9,"") -> 64 | F9: =IF(B9=E9,F8+1,IF(ISNUMBER(B9),F8,)) -> 2
B10: ADC: | D10: =COUNTIF(D11:D31,"v") -> 9 | E10: =IF(D10="v",B10,"") | F10: =IF(B10=E10,F9+1,IF(ISNUMBER(B10),F9,)) -> 0
B11: 6 | C11: A6/ PGA5_OF/ CMP5_HP0/ CMP5_LP0/ AIO228 | E11: =IF(D11="v",B11,"") | F11: =IF(B11=E11,F10+1,IF(ISNUMBER(B11),F10,)) -> 0
B12: 7 | C12: B2/ C6/ PGA3_OF/ CMP3_HP0/ CMP3_LP0/ AIO226 | E12: =IF(D12="v",B12,"") | F12: =IF(B12=E12,F11+1,IF(ISNUMBER(B12),F11,)) -> 0
B13: 8 | C13: B3/ VDAC/ CMP3_HP3/ CMP3_HN0/ CMP3_LP3/ CMP3_LN0/ AIO242 | E13: =IF(D13="v",B13,"") | F13: =IF(B13=E13,F12+1,IF(ISNUMBER(B13),F12,)) -> 0
B14: 9 | C14: A2/ B6/ PGA1_OF/ CMP1_HP0/ CMP1_LP0/ AIO224 | E14: =IF(D14="v",B14,"") | F14: =IF(B14=E14,F13+1,IF(ISNUMBER(B14),F13,)) -> 0
B15: 10 | C15: A3/ CMP1_HP3/ CMP1_HN0/ CMP1_LP3/ CMP1_LN0/ AIO233 | E15: =IF(D15="v",B15,"") | F15: =IF(B15=E15,F14+1,IF(ISNUMBER(B15),F14,)) -> 0
B16: 17 | C16: C4/ CMP5_HP1/ CMP5_HN1/ CMP5_LP1/ CMP5_LN1/ AIO239 | D16: v | E16: =IF(D16="v",B16,"") -> 17 | F16: =IF(B16=E16,F15+1,IF(ISNUMBER(B16),F15,)) -> 1
B17: 19 | C17: C0/ CMP1_HP1/ CMP1_HN1/ CMP1_LP1/ CMP1_LN1/ AIO237 | D17: v | E17: =IF(D17="v",B17,"") -> 19 | F17: =IF(B17=E17,F16+1,IF(ISNUMBER(B17),F16,)) -> 2
B18: 21 | C18: C2/ CMP3_HP1/ CMP3_HN1/ CMP3_LP1/ CMP3_LN1/ AIO244 | D18: v | E18: =IF(D18="v",B18,"") -> 21 | F18: =IF(B18=E18,F17+1,IF(ISNUMBER(B18),F17,)) -> 3
B19: 22 | C19: A1/ DACB_OUT/ AIO232 | E19: =IF(D19="v",B19,"") | F19: =IF(B19=E19,F18+1,IF(ISNUMBER(B19),F18,)) -> 3
B20: 23 | C20: A0/ B15/ C15/ DACA_OUT/ AIO231 | E20: =IF(D20="v",B20,"") | F20: =IF(B20=E20,F19+1,IF(ISNUMBER(B20),F19,)) -> 3
B21: 28 | C21: C5/ CMP6_HP1/ CMP6_HN1/ CMP6_LP1/ CMP6_LN1/ PGA6_IN/ CMP6_HP2/ CMP6_LP2/ AIO240 | E21: =IF(D21="v",B21,"") | F21: =IF(B21=E21,F20+1,IF(ISNUMBER(B21),F20,)) -> 3
B22: 29 | C22: C1/ CMP2_HP1/ CMP2_HN1/ CMP2_LP1/ CMP2_LN1/ AIO238 | D22: v | E22: =IF(D22="v",B22,"") -> 29 | F22: =IF(B22=E22,F21+1,IF(ISNUMBER(B22),F21,)) -> 4
B23: 31 | C23: C3/ CMP4_HP1/ CMP4_HN1/ CMP4_LP1/ CMP4_LN1/ PGA4_IN/ CMP4_HP2/ CMP4_LP2/ AIO245 | D23: v | E23: =IF(D23="v",B23,"") -> 31 | F23: =IF(B23=E23,F22+1,IF(ISNUMBER(B23),F22,)) -> 5
B24: 35 | C24: A5/ CMP2_HP3/ CMP2_HN0/ CMP2_LP3/ CMP2_LN0/ AIO234 | E24: =IF(D24="v",B24,"") | F24: =IF(B24=E24,F23+1,IF(ISNUMBER(B24),F23,)) -> 5
B25: 36 | C25: A4/ B8/ PGA2_OF/ CMP2_HP0/ CMP2_LP0/ AIO225 | D25: v | E25: =IF(D25="v",B25,"") -> 36 | F25: =IF(B25=E25,F24+1,IF(ISNUMBER(B25),F24,)) -> 6
B26: 37 | C26: A8/ PGA6_OF/ CMP6_HP0/ CMP6_LP0/ AIO229 | D26: v | E26: =IF(D26="v",B26,"") -> 37 | F26: =IF(B26=E26,F25+1,IF(ISNUMBER(B26),F25,)) -> 7
B27: 38 | C27: A9/ CMP6_HP3/ CMP6_HN0/ CMP6_LP3/ CMP6_LN0/ AIO236 | D27: v | E27: =IF(D27="v",B27,"") -> 38 | F27: =IF(B27=E27,F26+1,IF(ISNUMBER(B27),F26,)) -> 8
B28: 39 | C28: B4/ C8/ PGA4_OF/ CMP4_HP0/ CMP4_LP0/ AIO227 | E28: =IF(D28="v",B28,"") | F28: =IF(B28=E28,F27+1,IF(ISNUMBER(B28),F27,)) -> 8
B29: 40 | C29: A10/ B1/ C10/ PGA7_OF/ CMP7_HP0/ CMP7_LP0/ AIO230 | E29: =IF(D29="v",B29,"") | F29: =IF(B29=E29,F28+1,IF(ISNUMBER(B29),F28,)) -> 8
B30: 41 | C30: B0/ CMP7_HP3/ CMP7_HN0/ CMP7_LP3/ CMP7_LN0/ AIO241 | D30: v | E30: =IF(D30="v",B30,"") -> 41 | F30: =IF(B30=E30,F29+1,IF(ISNUMBER(B30),F29,)) -> 9
B31: 44 | C31: C14/ CMP7_HP1/ CMP7_HN1/ CMP7_LP1/ CMP7_LN1/ AIO246 | E31: =IF(D31="v",B31,"") | F31: =IF(B31=E31,F30+1,IF(ISNUMBER(B31),F30,)) -> 9
B32: COMP: | D32: =COUNTIF(D33:D56,"v") -> 4 | E32: =IF(D32="v",B32,"") | F32: =IF(B32=E32,F31+1,IF(ISNUMBER(B32),F31,)) -> 0
B33: 6 | C33: A6/ PGA5_OF/ CMP5_HP0/ CMP5_LP0/ AIO228 | E33: =IF(D33="v",B33,"") | F33: =IF(B33=E33,F32+1,IF(ISNUMBER(B33),F32,)) -> 0
B34: 7 | C34: B2/ C6/ PGA3_OF/ CMP3_HP0/ CMP3_LP0/ AIO226 | E34: =IF(D34="v",B34,"") | F34: =IF(B34=E34,F33+1,IF(ISNUMBER(B34),F33,)) -> 0
B35: 8 | C35: B3/ VDAC/ CMP3_HP3/ CMP3_HN0/ CMP3_LP3/ CMP3_LN0/ AIO242 | E35: =IF(D35="v",B35,"") | F35: =IF(B35=E35,F34+1,IF(ISNUMBER(B35),F34,)) -> 0
B36: 9 | C36: A2/ B6/ PGA1_OF/ CMP1_HP0/ CMP1_LP0/ AIO224 | E36: =IF(D36="v",B36,"") | F36: =IF(B36=E36,F35+1,IF(ISNUMBER(B36),F35,)) -> 0
B37: 10 | C37: A3/ CMP1_HP3/ CMP1_HN0/ CMP1_LP3/ CMP1_LN0/ AIO233 | D37: v | E37: =IF(D37="v",B37,"") -> 10 | F37: =IF(B37=E37,F36+1,IF(ISNUMBER(B37),F36,)) -> 1
B38: 16 | C38: PGA5_IN/ CMP5_HP2/ CMP5_LP2 | E38: =IF(D38="v",B38,"") | F38: =IF(B38=E38,F37+1,IF(ISNUMBER(B38),F37,)) -> 1
B39: 17 | C39: C4/ CMP5_HP1/ CMP5_HN1/ CMP5_LP1/ CMP5_LN1/ AIO239 | E39: =IF(D39="v",B39,"") | F39: =IF(B39=E39,F38+1,IF(ISNUMBER(B39),F38,)) -> 1
B40: 18 | C40: PGA1_IN/ CMP1_HP2/ CMP1_LP2 | E40: =IF(D40="v",B40,"") | F40: =IF(B40=E40,F39+1,IF(ISNUMBER(B40),F39,)) -> 1
...

Sheet ADC
B1: Index | C1: Pin | D1: Name | E1: Connect to | F1: Type | G1: Function Description
B2: 1 | C2: =IFERROR(OFFSET(Assign!$B$11,MATCH($B2,Assign!$F$11:$F$31,0)-1,0),"") -> 17 | D2: =IFERROR(OFFSET(Assign!$C$11,MATCH($B2,Assign!$F$11:$F$31,0)-1,0),"") -> C4/ CMP5_HP1/ CMP5_HN1/ CMP5_LP1/ CMP5_LN1/ AIO239 | E2: ADC_NTC_AMBF | F2: ADC | G2: Ambient temperature sensor
B3: 2 | C3: =IFERROR(OFFSET(Assign!$B$11,MATCH($B3,Assign!$F$11:$F$31,0)-1,0),"") -> 19 | D3: =IFERROR(OFFSET(Assign!$C$11,MATCH($B3,Assign!$F$11:$F$31,0)-1,0),"") -> C0/ CMP1_HP1/ CMP1_HN1/ CMP1_LP1/ CMP1_LN1/ AIO237 | E3: ADC_CT1_I_PFC | F3: ADC & CMP | G3: Inductor current of phase 1 PFC inductor current with input of CMP1_HP1
B4: 3 | C4: =IFERROR(OFFSET(Assign!$B$11,MATCH($B4,Assign!$F$11:$F$31,0)-1,0),"") -> 21 | D4: =IFERROR(OFFSET(Assign!$C$11,MATCH($B4,Assign!$F$11:$F$31,0)-1,0),"") -> C2/ CMP3_HP1/ CMP3_HN1/ CMP3_LP1/ CMP3_LN1/ AIO244 | E4: ADC_NTC_PFC | F4: ADC | G4: PFC heatsink temperature sensor
B5: 4 | C5: =IFERROR(OFFSET(Assign!$B$11,MATCH($B5,Assign!$F$11:$F$31,0)-1,0),"") -> 29 | D5: =IFERROR(OFFSET(Assign!$C$11,MATCH($B5,Assign!$F$11:$F$31,0)-1,0),"") -> C1/ CMP2_HP1/ CMP2_HN1/ CMP2_LP1/ CMP2_LN1/ AIO238 | E5: ADC_CT2_I_PFC | F5: ADC & CMP | G5: Inductor current of phase 2 PFC inductor current with input of CMP2_HP1
B6: 5 | C6: =IFERROR(OFFSET(Assign!$B$11,MATCH($B6,Assign!$F$11:$F$31,0)-1,0),"") -> 31 | D6: =IFERROR(OFFSET(Assign!$C$11,MATCH($B6,Assign!$F$11:$F$31,0)-1,0),"") -> C3/ CMP4_HP1/ CMP4_HN1/ CMP4_LP1/ CMP4_LN1/ PGA4_IN/ CMP4_HP2/ CMP4_LP2/ AIO245 | E6: ADC_VBULK | F6: ADC | G6: Bulk voltage
B7: 6 | C7: =IFERROR(OFFSET(Assign!$B$11,MATCH($B7,Assign!$F$11:$F$31,0)-1,0),"") -> 36 | D7: =IFERROR(OFFSET(Assign!$C$11,MATCH($B7,Assign!$F$11:$F$31,0)-1,0),"") -> A4/ B8/ PGA2_OF/ CMP2_HP0/ CMP2_LP0/ AIO225 | E7: ADC_VAC_L | F7: ADC | G7: Input AC line
B8: 7 | C8: =IFERROR(OFFSET(Assign!$B$11,MATCH($B8,Assign!$F$11:$F$31,0)-1,0),"") -> 37 | D8: =IFERROR(OFFSET(Assign!$C$11,MATCH($B8,Assign!$F$11:$F$31,0)-1,0),"") -> A8/ PGA6_OF/ CMP6_HP0/ CMP6_LP0/ AIO229 | E8: ADC_VAC_N | F8: ADC | G8: Input AC natural
B9: 8 | C9: =IFERROR(OFFSET(Assign!$B$11,MATCH($B9,Assign!$F$11:$F$31,0)-1,0),"") -> 38 | D9: =IFERROR(OFFSET(Assign!$C$11,MATCH($B9,Assign!$F$11:$F$31,0)-1,0),"") -> A9/ CMP6_HP3/ CMP6_HN0/ CMP6_LP3/ CMP6_LN0/ AIO236 | E9: ADC_CT3_I_PFC | F9: ADC & CMP | G9: Inductor current of phase 3 PFC inductor current with input of CMP6_HP3
B10: 9 | C10: =IFERROR(OFFSET(Assign!$B$11,MATCH($B10,Assign!$F$11:$F$31,0)-1,0),"") -> 41 | D10: =IFERROR(OFFSET(Assign!$C$11,MATCH($B10,Assign!$F$11:$F$31,0)-1,0),"") -> B0/ CMP7_HP3/ CMP7_HN0/ CMP7_LP3/ CMP7_LN0/ AIO241 | E10: ADC_CT4_I_PFC | F10: ADC & CMP | G10: Inductor current of phase 4 PFC inductor current with input of CMP7_HP3
B11: 10 | C11: =IFERROR(OFFSET(Assign!$B$11,MATCH($B11,Assign!$F$11:$F$31,0)-1,0),"") | D11: =IFERROR(OFFSET(Assign!$C$11,MATCH($B11,Assign!$F$11:$F$31,0)-1,0),"")
B12: 11 | C12: =IFERROR(OFFSET(Assign!$B$11,MATCH($B12,Assign!$F$11:$F$31,0)-1,0),"") | D12: =IFERROR(OFFSET(Assign!$C$11,MATCH($B12,Assign!$F$11:$F$31,0)-1,0),"")
B13: 12 | C13: =IFERROR(OFFSET(Assign!$B$11,MATCH($B13,Assign!$F$11:$F$31,0)-1,0),"") | D13: =IFERROR(OFFSET(Assign!$C$11,MATCH($B13,Assign!$F$11:$F$31,0)-1,0),"")
B14: 13 | C14: =IFERROR(OFFSET(Assign!$B$11,MATCH($B14,Assign!$F$11:$F$31,0)-1,0),"") | D14: =IFERROR(OFFSET(Assign!$C$11,MATCH($B14,Assign!$F$11:$F$31,0)-1,0),"")
B15: 14 | C15: =IFERROR(OFFSET(Assign!$B$11,MATCH($B15,Assign!$F$11:$F$31,0)-1,0),"") | D15: =IFERROR(OFFSET(Assign!$C$11,MATCH($B15,Assign!$F$11:$F$31,0)-1,0),"")
B16: 15 | C16: =IFERROR(OFFSET(Assign!$B$11,MATCH($B16,Assign!$F$11:$F$31,0)-1,0),"") | D16: =IFERROR(OFFSET(Assign!$C$11,MATCH($B16,Assign!$F$11:$F$31,0)-1,0),"")
B17: 16 | C17: =IFERROR(OFFSET(Assign!$B$11,MATCH($B17,Assign!$F$11:$F$31,0)-1,0),"") | D17: =IFERROR(OFFSET(Assign!$C$11,MATCH($B17,Assign!$F$11:$F$31,0)-1,0),"")
B18: 17 | C18: =IFERROR(OFFSET(Assign!$B$11,MATCH($B18,Assign!$F$11:$F$31,0)-1,0),"") | D18: =IFERROR(OFFSET(Assign!$C$11,MATCH($B18,Assign!$F$11:$F$31,0)-1,0),"")
B19: 18 | C19: =IFERROR(OFFSET(Assign!$B$11,MATCH($B19,Assign!$F$11:$F$31,0)-1,0),"") | D19: =IFERROR(OFFSET(Assign!$C$11,MATCH($B19,Assign!$F$11:$F$31,0)-1,0),"")
B20: 19 | C20: =IFERROR(OFFSET(Assign!$B$11,MATCH($B20,Assign!$F$11:$F$31,0)-1,0),"") | D20: =IFERROR(OFFSET(Assign!$C$11,MATCH($B20,Assign!$F$11:$F$31,0)-1,0),"")
B21: 20 | C21: =IFERROR(OFFSET(Assign!$B$11,MATCH($B21,Assign!$F$11:$F$31,0)-1,0),"") | D21: =IFERROR(OFFSET(Assign!$C$11,MATCH($B21,Assign!$F$11:$F$31,0)-1,0),"")
B22: 21 | C22: =IFERROR(OFFSET(Assign!$B$11,MATCH($B22,Assign!$F$11:$F$31,0)-1,0),"") | D22: =IFERROR(OFFSET(Assign!$C$11,MATCH($B22,Assign!$F$11:$F$31,0)-1,0),"")
... B101: 100 | C101: =IFERROR(OFFSET(Assign!$B$11,MATCH($B101,Assign!$F$11:$F$31,0)-1,0),"") | D101: =IFERROR(OFFSET(Assign!$C$11,MATCH($B101,Assign!$F$11:$F$31,0)-1,0),"")

Sheet COMP
B1: Index | C1: Pin | D1: Name | E1: Connect to | F1: Type | G1: Function Description
B2: 1 | C2: =IFERROR(OFFSET(Assign!$B$33,MATCH($B2,Assign!$F$33:$F$56,0)-1,0),"") -> 10 | D2: =IFERROR(OFFSET(Assign!$C$33,MATCH($B2,Assign!$F$33:$F$56,0)-1,0),"") -> A3/ CMP1_HP3/ CMP1_HN0/ CMP1_LP3/ CMP1_LN0/ AIO233 | E2: ADC_PK1_3_LIM | F2: CMP | G2: Slope compensation refence of phase 1 and 3 with input of CMP1_HN0
B3: 2 | C3: =IFERROR(OFFSET(Assign!$B$33,MATCH($B3,Assign!$F$33:$F$56,0)-1,0),"") -> 28 | D3: =IFERROR(OFFSET(Assign!$C$33,MATCH($B3,Assign!$F$33:$F$56,0)-1,0),"") -> C5/ CMP6_HP1/ CMP6_HN1/ CMP6_LP1/ CMP6_LN1/ PGA6_IN/ CMP6_HP2/ CMP6_LP2/ AIO240 | E3: ADC_PK2_4_LIM | F3: CMP | G3: Slope compensation refence of phase 2 and 4 with input CMP6_HN1
B4: 3 | C4: =IFERROR(OFFSET(Assign!$B$33,MATCH($B4,Assign!$F$33:$F$56,0)-1,0),"") -> 35 | D4: =IFERROR(OFFSET(Assign!$C$33,MATCH($B4,Assign!$F$33:$F$56,0)-1,0),"") -> A5/ CMP2_HP3/ CMP2_HN0/ CMP2_LP3/ CMP2_LN0/ AIO234 | E4: ADC_PK1_3_LIM | F4: CMP | G4: Slope compensation refence of phase 1 and 3 with input CMP2_HN0
B5: 4 | C5: =IFERROR(OFFSET(Assign!$B$33,MATCH($B5,Assign!$F$33:$F$56,0)-1,0),"") -> 44 | D5: =IFERROR(OFFSET(Assign!$C$33,MATCH($B5,Assign!$F$33:$F$56,0)-1,0),"") -> C14/ CMP7_HP1/ CMP7_HN1/ CMP7_LP1/ CMP7_LN1/ AIO246 | E5: ADC_PK2_4_LIM | F5: CMP | G5: Slope compensation refence of phase 2 and 4 with input CMP7_HN1
B6: 5 | C6: =IFERROR(OFFSET(Assign!$B$33,MATCH($B6,Assign!$F$33:$F$56,0)-1,0),"") | D6: =IFERROR(OFFSET(Assign!$C$33,MATCH($B6,Assign!$F$33:$F$56,0)-1,0),"")
B7: 6 | C7: =IFERROR(OFFSET(Assign!$B$33,MATCH($B7,Assign!$F$33:$F$56,0)-1,0),"") | D7: =IFERROR(OFFSET(Assign!$C$33,MATCH($B7,Assign!$F$33:$F$56,0)-1,0),"")
B8: 7 | C8: =IFERROR(OFFSET(Assign!$B$33,MATCH($B8,Assign!$F$33:$F$56,0)-1,0),"") | D8: =IFERROR(OFFSET(Assign!$C$33,MATCH($B8,Assign!$F$33:$F$56,0)-1,0),"")
B9: 8 | C9: =IFERROR(OFFSET(Assign!$B$33,MATCH($B9,Assign!$F$33:$F$56,0)-1,0),"") | D9: =IFERROR(OFFSET(Assign!$C$33,MATCH($B9,Assign!$F$33:$F$56,0)-1,0),"")
B10: 9 | C10: =IFERROR(OFFSET(Assign!$B$33,MATCH($B10,Assign!$F$33:$F$56,0)-1,0),"") | D10: =IFERROR(OFFSET(Assign!$C$33,MATCH($B10,Assign!$F$33:$F$56,0)-1,0),"")
B11: 10 | C11: =IFERROR(OFFSET(Assign!$B$33,MATCH($B11,Assign!$F$33:$F$56,0)-1,0),"") | D11: =IFERROR(OFFSET(Assign!$C$33,MATCH($B11,Assign!$F$33:$F$56,0)-1,0),"")
B12: 11 | C12: =IFERROR(OFFSET(Assign!$B$33,MATCH($B12,Assign!$F$33:$F$56,0)-1,0),"") | D12: =IFERROR(OFFSET(Assign!$C$33,MATCH($B12,Assign!$F$33:$F$56,0)-1,0),"")
B13: 12 | C13: =IFERROR(OFFSET(Assign!$B$33,MATCH($B13,Assign!$F$33:$F$56,0)-1,0),"") | D13: =IFERROR(OFFSET(Assign!$C$33,MATCH($B13,Assign!$F$33:$F$56,0)-1,0),"")
B14: 13 | C14: =IFERROR(OFFSET(Assign!$B$33,MATCH($B14,Assign!$F$33:$F$56,0)-1,0),"") | D14: =IFERROR(OFFSET(Assign!$C$33,MATCH($B14,Assign!$F$33:$F$56,0)-1,0),"")
B15: 14 | C15: =IFERROR(OFFSET(Assign!$B$33,MATCH($B15,Assign!$F$33:$F$56,0)-1,0),"") | D15: =IFERROR(OFFSET(Assign!$C$33,MATCH($B15,Assign!$F$33:$F$56,0)-1,0),"")
B16: 15 | C16: =IFERROR(OFFSET(Assign!$B$33,MATCH($B16,Assign!$F$33:$F$56,0)-1,0),"") | D16: =IFERROR(OFFSET(Assign!$C$33,MATCH($B16,Assign!$F$33:$F$56,0)-1,0),"")
B17: 16 | C17: =IFERROR(OFFSET(Assign!$B$33,MATCH($B17,Assign!$F$33:$F$56,0)-1,0),"") | D17: =IFERROR(OFFSET(Assign!$C$33,MATCH($B17,Assign!$F$33:$F$56,0)-1,0),"")
... B101: 100 | C101: =IFERROR(OFFSET(Assign!$B$33,MATCH($B101,Assign!$F$33:$F$56,0)-1,0),"") | D101: =IFERROR(OFFSET(Assign!$C$33,MATCH($B101,Assign!$F$33:$F$56,0)-1,0),"")

Sheet PGA
B1: Index | C1: Pin | D1: Name | E1: Connect to | F1: Type | G1: Function Description
B2: 1 | C2: =IFERROR(OFFSET(Assign!$B$58,MATCH($B2,Assign!$F$58:$F$76,0)-1,0),"") | D2: =IFERROR(OFFSET(Assign!$C$58,MATCH($B2,Assign!$F$58:$F$76,0)-1,0),"")
B3: 2 | C3: =IFERROR(OFFSET(Assign!$B$58,MATCH($B3,Assign!$F$58:$F$76,0)-1,0),"") | D3: =IFERROR(OFFSET(Assign!$C$58,MATCH($B3,Assign!$F$58:$F$76,0)-1,0),"")
B4: 3 | C4: =IFERROR(OFFSET(Assign!$B$58,MATCH($B4,Assign!$F$58:$F$76,0)-1,0),"") | D4: =IFERROR(OFFSET(Assign!$C$58,MATCH($B4,Assign!$F$58:$F$76,0)-1,0),"")
B5: 4 | C5: =IFERROR(OFFSET(Assign!$B$58,MATCH($B5,Assign!$F$58:$F$76,0)-1,0),"") | D5: =IFERROR(OFFSET(Assign!$C$58,MATCH($B5,Assign!$F$58:$F$76,0)-1,0),"")
B6: 5 | C6: =IFERROR(OFFSET(Assign!$B$58,MATCH($B6,Assign!$F$58:$F$76,0)-1,0),"") | D6: =IFERROR(OFFSET(Assign!$C$58,MATCH($B6,Assign!$F$58:$F$76,0)-1,0),"")
B7: 6 | C7: =IFERROR(OFFSET(Assign!$B$58,MATCH($B7,Assign!$F$58:$F$76,0)-1,0),"") | D7: =IFERROR(OFFSET(Assign!$C$58,MATCH($B7,Assign!$F$58:$F$76,0)-1,0),"")
B8: 7 | C8: =IFERROR(OFFSET(Assign!$B$58,MATCH($B8,Assign!$F$58:$F$76,0)-1,0),"") | D8: =IFERROR(OFFSET(Assign!$C$58,MATCH($B8,Assign!$F$58:$F$76,0)-1,0),"")
B9: 8 | C9: =IFERROR(OFFSET(Assign!$B$58,MATCH($B9,Assign!$F$58:$F$76,0)-1,0),"") | D9: =IFERROR(OFFSET(Assign!$C$58,MATCH($B9,Assign!$F$58:$F$76,0)-1,0),"")
B10: 9 | C10: =IFERROR(OFFSET(Assign!$B$58,MATCH($B10,Assign!$F$58:$F$76,0)-1,0),"") | D10: =IFERROR(OFFSET(Assign!$C$58,MATCH($B10,Assign!$F$58:$F$76,0)-1,0),"")
B11: 10 | C11: =IFERROR(OFFSET(Assign!$B$58,MATCH($B11,Assign!$F$58:$F$76,0)-1,0),"") | D11: =IFERROR(OFFSET(Assign!$C$58,MATCH($B11,Assign!$F$58:$F$76,0)-1,0),"")
B12: 11 | C12: =IFERROR(OFFSET(Assign!$B$58,MATCH($B12,Assign!$F$58:$F$76,0)-1,0),"") | D12: =IFERROR(OFFSET(Assign!$C$58,MATCH($B12,Assign!$F$58:$F$76,0)-1,0),"")
B13: 12 | C13: =IFERROR(OFFSET(Assign!$B$58,MATCH($B13,Assign!$F$58:$F$76,0)-1,0),"") | D13: =IFERROR(OFFSET(Assign!$C$58,MATCH($B13,Assign!$F$58:$F$76,0)-1,0),"")
... B101: 100 | C101: =IFERROR(OFFSET(Assign!$B$58,MATCH($B101,Assign!$F$58:$F$76,0)-1,0),"") | D101: =IFERROR(OFFSET(Assign!$C$58,MATCH($B101,Assign!$F$58:$F$76,0)-1,0),"")

Sheet DAC
B1: Index | C1: Pin | D1: Name | E1: Connect to | F1: Type | G1: Function Description
B2: 1 | C2: =IFERROR(OFFSET(Assign!$B$78,MATCH($B2,Assign!$F$78:$F$80,0)-1,0),"") -> 22 | D2: =IFERROR(OFFSET(Assign!$C$78,MATCH($B2,Assign!$F$78:$F$80,0)-1,0),"") -> A1/ DACB_OUT/ AIO232 | E2: DAC_TEST1 | F2: DAC | G2: DACB_OUT for debug
B3: 2 | C3: =IFERROR(OFFSET(Assign!$B$78,MATCH($B3,Assign!$F$78:$F$80,0)-1,0),"") -> 23 | D3: =IFERROR(OFFSET(Assign!$C$78,MATCH($B3,Assign!$F$78:$F$80,0)-1,0),"") -> A0/ B15/ C15/ DACA_OUT/ AIO231 | E3: DAC_TEST2 | F3: DAC | G3: DACA_OUT for debug
B4: 3 | C4: =IFERROR(OFFSET(Assign!$B$78,MATCH($B4,Assign!$F$78:$F$80,0)-1,0),"") | D4: =IFERROR(OFFSET(Assign!$C$78,MATCH($B4,Assign!$F$78:$F$80,0)-1,0),"")
B5: 4 | C5: =IFERROR(OFFSET(Assign!$B$78,MATCH($B5,Assign!$F$78:$F$80,0)-1,0),"") | D5: =IFERROR(OFFSET(Assign!$C$78,MATCH($B5,Assign!$F$78:$F$80,0)-1,0),"")
B6: 5 | C6: =IFERROR(OFFSET(Assign!$B$78,MATCH($B6,Assign!$F$78:$F$80,0)-1,0),"") | D6: =IFERROR(OFFSET(Assign!$C$78,MATCH($B6,Assign!$F$78:$F$80,0)-1,0),"")
B7: 6 | C7: =IFERROR(OFFSET(Assign!$B$78,MATCH($B7,Assign!$F$78:$F$80,0)-1,0),"") | D7: =IFERROR(OFFSET(Assign!$C$78,MATCH($B7,Assign!$F$78:$F$80,0)-1,0),"")
B8: 7 | C8: =IFERROR(OFFSET(Assign!$B$78,MATCH($B8,Assign!$F$78:$F$80,0)-1,0),"") | D8: =IFERROR(OFFSET(Assign!$C$78,MATCH($B8,Assign!$F$78:$F$80,0)-1,0),"")
B9: 8 | C9: =IFERROR(OFFSET(Assign!$B$78,MATCH($B9,Assign!$F$78:$F$80,0)-1,0),"") | D9: =IFERROR(OFFSET(Assign!$C$78,MATCH($B9,Assign!$F$78:$F$80,0)-1,0),"")
B10: 9 | C10: =IFERROR(OFFSET(Assign!$B$78,MATCH($B10,Assign!$F$78:$F$80,0)-1,0),"") | D10: =IFERROR(OFFSET(Assign!$C$78,MATCH($B10,Assign!$F$78:$F$80,0)-1,0),"")
B11: 10 | C11: =IFERROR(OFFSET(Assign!$B$78,MATCH($B11,Assign!$F$78:$F$80,0)-1,0),"") | D11: =IFERROR(OFFSET(Assign!$C$78,MATCH($B11,Assign!$F$78:$F$80,0)-1,0),"")
B12: 11 | C12: =IFERROR(OFFSET(Assign!$B$78,MATCH($B12,Assign!$F$78:$F$80,0)-1,0),"") | D12: =IFERROR(OFFSET(Assign!$C$78,MATCH($B12,Assign!$F$78:$F$80,0)-1,0),"")
B13: 12 | C13: =IFERROR(OFFSET(Assign!$B$78,MATCH($B13,Assign!$F$78:$F$80,0)-1,0),"") | D13: =IFERROR(OFFSET(Assign!$C$78,MATCH($B13,Assign!$F$78:$F$80,0)-1,0),"")
B14: 13 | C14: =IFERROR(OFFSET(Assign!$B$78,MATCH($B14,Assign!$F$78:$F$80,0)-1,0),"") | D14: =IFERROR(OFFSET(Assign!$C$78,MATCH($B14,Assign!$F$78:$F$80,0)-1,0),"")
B15: 14 | C15: =IFERROR(OFFSET(Assign!$B$78,MATCH($B15,Assign!$F$78:$F$80,0)-1,0),"") | D15: =IFERROR(OFFSET(Assign!$C$78,MATCH($B15,Assign!$F$78:$F$80,0)-1,0),"")
... B101: 100 | C101: =IFERROR(OFFSET(Assign!$B$78,MATCH($B101,Assign!$F$78:$F$80,0)-1,0),"") | D101: =IFERROR(OFFSET(Assign!$C$78,MATCH($B101,Assign!$F$78:$F$80,0)-1,0),"")

Sheet EPWM
B1: Index | C1: Pin | D1: Name | E1: Connect to | F1: Type | G1: Function Description
B2: 1 | C2: =IFERROR(OFFSET(Assign!$B$82,MATCH($B2,Assign!$F$82:$F$104,0)-1,0),"") -> 1 | D2: =IFERROR(OFFSET(Assign!$C$82,MATCH($B2,Assign!$F$82:$F$104,0)-1,0),"") -> GPIO28/ SCIA_RX/ EPWM7_A/ OUTPUTXBAR5/ EQEP1_A/ SD1_D3/ EQEP2_STROBE/ LINA_TX/ SPIB_CLK/ ERRORSTS | E2: EPWM_PFC_L | F2: PWM | G2: PWM7_A for input SR
B3: 2 | C3: =IFERROR(OFFSET(Assign!$B$82,MATCH($B3,Assign!$F$82:$F$104,0)-1,0),"") -> 52 | D3: =IFERROR(OFFSET(Assign!$C$82,MATCH($B3,Assign!$F$82:$F$104,0)-1,0),"") -> GPIO11/ EPWM6_B/ SCIB_RX/ OUTPUTXBAR7/ EQEP1_B/ SPIA_STE/ FSIRXA_D1 | E3: EPWM_FAN2_CTRL | F3: PWM | G3: PWM6_B for Fan2 control
B4: 3 | C4: =IFERROR(OFFSET(Assign!$B$82,MATCH($B4,Assign!$F$82:$F$104,0)-1,0),"") -> 75 | D4: =IFERROR(OFFSET(Assign!$C$82,MATCH($B4,Assign!$F$82:$F$104,0)-1,0),"") -> GPIO4/ EPWM3_A/ OUTPUTXBAR3/ CANA_TX/ FSIRXA_CLK | E4: EPWM_PFC_PH3 | F4: PWM | G4: PWM3_A for PFC phase 3
B5: 4 | C5: =IFERROR(OFFSET(Assign!$B$82,MATCH($B5,Assign!$F$82:$F$104,0)-1,0),"") -> 77 | D5: =IFERROR(OFFSET(Assign!$C$82,MATCH($B5,Assign!$F$82:$F$104,0)-1,0),"") -> GPIO2/ EPWM2_A/ OUTPUTXBAR1/ PMBUSA_SDA/ SCIA_TX/ FSIRXA_D1 | E5: EPWM_PFC_PH2 | F5: PWM | G5: PWM2_A for PFC phase 2
B6: 5 | C6: =IFERROR(OFFSET(Assign!$B$82,MATCH($B6,Assign!$F$82:$F$104,0)-1,0),"") -> 79 | D6: =IFERROR(OFFSET(Assign!$C$82,MATCH($B6,Assign!$F$82:$F$104,0)-1,0),"") -> GPIO0/ EPWM1_A/ I2CA_SDA | E6: EPWM_PFC_PH1 | F6: PWM | G6: PWM1_A for PFC phase 1
B7: 6 | C7: =IFERROR(OFFSET(Assign!$B$82,MATCH($B7,Assign!$F$82:$F$104,0)-1,0),"") -> 93 | D7: =IFERROR(OFFSET(Assign!$C$82,MATCH($B7,Assign!$F$82:$F$104,0)-1,0),"") -> GPIO10/ EPWM6_A/ CANB_RX/ ADCSOCBO/ EQEP1_A/ SCIB_TX/ SPIA_SOMI/ I2CA_SDA/ FSITXA_CLK | E7: EPWM_FAN1_CTRL | F7: PWM | G7: PWM6_A for Fan1 control
B8: 7 | C8: =IFERROR(OFFSET(Assign!$B$82,MATCH($B8,Assign!$F$82:$F$104,0)-1,0),"") -> 97 | D8: =IFERROR(OFFSET(Assign!$C$82,MATCH($B8,Assign!$F$82:$F$104,0)-1,0),"") -> GPIO6/ EPWM4_A/ OUTPUTXBAR4/ SYNCOUT/ EQEP1_A/ CANB_TX/ SPIB_SOMI/ FSITXA_D0 | E8: EPWM_PFC_PH4 | F8: PWM | G8: PWM4_A for PFC phase 4
B9: 8 | C9: =IFERROR(OFFSET(Assign!$B$82,MATCH($B9,Assign!$F$82:$F$104,0)-1,0),"") -> 100 | D9: =IFERROR(OFFSET(Assign!$C$82,MATCH($B9,Assign!$F$82:$F$104,0)-1,0),"") -> GPIO29/ SCIA_TX/ EPWM7_B/ OUTPUTXBAR6/ EQEP1_B/ SD1_C3/ EQEP2_INDEX/ LINA_RX/ SPIB_STE/ ERRORSTS | E9: EPWM_PFC_N | F9: PWM | G9: PWM7_B for input SR
B10: 9 | C10: =IFERROR(OFFSET(Assign!$B$82,MATCH($B10,Assign!$F$82:$F$104,0)-1,0),"") | D10: =IFERROR(OFFSET(Assign!$C$82,MATCH($B10,Assign!$F$82:$F$104,0)-1,0),"")
B11: 10 | C11: =IFERROR(OFFSET(Assign!$B$82,MATCH($B11,Assign!$F$82:$F$104,0)-1,0),"") | D11: =IFERROR(OFFSET(Assign!$C$82,MATCH($B11,Assign!$F$82:$F$104,0)-1,0),"")
B12: 11 | C12: =IFERROR(OFFSET(Assign!$B$82,MATCH($B12,Assign!$F$82:$F$104,0)-1,0),"") | D12: =IFERROR(OFFSET(Assign!$C$82,MATCH($B12,Assign!$F$82:$F$104,0)-1,0),"")
B13: 12 | C13: =IFERROR(OFFSET(Assign!$B$82,MATCH($B13,Assign!$F$82:$F$104,0)-1,0),"") | D13: =IFERROR(OFFSET(Assign!$C$82,MATCH($B13,Assign!$F$82:$F$104,0)-1,0),"")
B14: 13 | C14: =IFERROR(OFFSET(Assign!$B$82,MATCH($B14,Assign!$F$82:$F$104,0)-1,0),"") | D14: =IFERROR(OFFSET(Assign!$C$82,MATCH($B14,Assign!$F$82:$F$104,0)-1,0),"")
B15: 14 | C15: =IFERROR(OFFSET(Assign!$B$82,MATCH($B15,Assign!$F$82:$F$104,0)-1,0),"") | D15: =IFERROR(OFFSET(Assign!$C$82,MATCH($B15,Assign!$F$82:$F$104,0)-1,0),"")
B16: 15 | C16: =IFERROR(OFFSET(Assign!$B$82,MATCH($B16,Assign!$F$82:$F$104,0)-1,0),"") | D16: =IFERROR(OFFSET(Assign!$C$82,MATCH($B16,Assign!$F$82:$F$104,0)-1,0),"")
B17: 16 | C17: =IFERROR(OFFSET(Assign!$B$82,MATCH($B17,Assign!$F$82:$F$104,0)-1,0),"") | D17: =IFERROR(OFFSET(Assign!$C$82,MATCH($B17,Assign!$F$82:$F$104,0)-1,0),"")
B18: 17 | C18: =IFERROR(OFFSET(Assign!$B$82,MATCH($B18,Assign!$F$82:$F$104,0)-1,0),"") | D18: =IFERROR(OFFSET(Assign!$C$82,MATCH($B18,Assign!$F$82:$F$104,0)-1,0),"")
B19: 18 | C19: =IFERROR(OFFSET(Assign!$B$82,MATCH($B19,Assign!$F$82:$F$104,0)-1,0),"") | D19: =IFERROR(OFFSET(Assign!$C$82,MATCH($B19,Assign!$F$82:$F$104,0)-1,0),"")
B20: 19 | C20: =IFERROR(OFFSET(Assign!$B$82,MATCH($B20,Assign!$F$82:$F$104,0)-1,0),"") | D20: =IFERROR(OFFSET(Assign!$C$82,MATCH($B20,Assign!$F$82:$F$104,0)-1,0),"")
B21: 20 | C21: =IFERROR(OFFSET(Assign!$B$82,MATCH($B21,Assign!$F$82:$F$104,0)-1,0),"") | D21: =IFERROR(OFFSET(Assign!$C$82,MATCH($B21,Assign!$F$82:$F$104,0)-1,0),"")
... B101: 100 | C101: =IFERROR(OFFSET(Assign!$B$82,MATCH($B101,Assign!$F$82:$F$104,0)-1,0),"") | D101: =IFERROR(OFFSET(Assign!$C$82,MATCH($B101,Assign!$F$82:$F$104,0)-1,0),"")

Sheet SCI
B1: Index | C1: Pin | D1: Name | E1: Connect to | F1: Type | G1: Function Description
B2: 1 | C2: =IFERROR(OFFSET(Assign!$B$106,MATCH($B2,Assign!$F$106:$F$128,0)-1,0),"") -> 54 | D2: =IFERROR(OFFSET(Assign!$C$106,MATCH($B2,Assign!$F$106:$F$128,0)-1,0),"") -> GPIO16/ SPIA_SIMO/ CANB_TX/ OUTPUTXBAR7/ EPWM5_A/ SCIA_TX/ SD1_D1/ EQEP1_STROBE/ PMBUSA_SCL/ XCLKOUT | E2: SCI_TX_PtS | F2: SCI | G2: SCIA_TX for internal Communication with secondary
B3: 2 | C3: =IFERROR(OFFSET(Assign!$B$106,MATCH($B3,Assign!$F$106:$F$128,0)-1,0),"") -> 55 | D3: =IFERROR(OFFSET(Assign!$C$106,MATCH($B3,Assign!$F$106:$F$128,0)-1,0),"") -> GPIO17/ SPIA_SOMI/ CANB_RX/ OUTPUTXBAR8/ EPWM5_B/ SCIA_RX/ SD1_C1/ EQEP1_INDEX/ PMBUSA_SDA | E3: SCI_RX_PtS | F3: SCI | G3: SCIA_RX for internal Communication with secondary
B4: 3 | C4: =IFERROR(OFFSET(Assign!$B$106,MATCH($B4,Assign!$F$106:$F$128,0)-1,0),"") | D4: =IFERROR(OFFSET(Assign!$C$106,MATCH($B4,Assign!$F$106:$F$128,0)-1,0),"")
B5: 4 | C5: =IFERROR(OFFSET(Assign!$B$106,MATCH($B5,Assign!$F$106:$F$128,0)-1,0),"") | D5: =IFERROR(OFFSET(Assign!$C$106,MATCH($B5,Assign!$F$106:$F$128,0)-1,0),"")
B6: 5 | C6: =IFERROR(OFFSET(Assign!$B$106,MATCH($B6,Assign!$F$106:$F$128,0)-1,0),"") | D6: =IFERROR(OFFSET(Assign!$C$106,MATCH($B6,Assign!$F$106:$F$128,0)-1,0),"")
B7: 6 | C7: =IFERROR(OFFSET(Assign!$B$106,MATCH($B7,Assign!$F$106:$F$128,0)-1,0),"") | D7: =IFERROR(OFFSET(Assign!$C$106,MATCH($B7,Assign!$F$106:$F$128,0)-1,0),"")
B8: 7 | C8: =IFERROR(OFFSET(Assign!$B$106,MATCH($B8,Assign!$F$106:$F$128,0)-1,0),"") | D8: =IFERROR(OFFSET(Assign!$C$106,MATCH($B8,Assign!$F$106:$F$128,0)-1,0),"")
B9: 8 | C9: =IFERROR(OFFSET(Assign!$B$106,MATCH($B9,Assign!$F$106:$F$128,0)-1,0),"") | D9: =IFERROR(OFFSET(Assign!$C$106,MATCH($B9,Assign!$F$106:$F$128,0)-1,0),"")
B10: 9 | C10: =IFERROR(OFFSET(Assign!$B$106,MATCH($B10,Assign!$F$106:$F$128,0)-1,0),"") | D10: =IFERROR(OFFSET(Assign!$C$106,MATCH($B10,Assign!$F$106:$F$128,0)-1,0),"")
B11: 10 | C11: =IFERROR(OFFSET(Assign!$B$106,MATCH($B11,Assign!$F$106:$F$128,0)-1,0),"") | D11: =IFERROR(OFFSET(Assign!$C$106,MATCH($B11,Assign!$F$106:$F$128,0)-1,0),"")
B12: 11 | C12: =IFERROR(OFFSET(Assign!$B$106,MATCH($B12,Assign!$F$106:$F$128,0)-1,0),"") | D12: =IFERROR(OFFSET(Assign!$C$106,MATCH($B12,Assign!$F$106:$F$128,0)-1,0),"")
B13: 12 | C13: =IFERROR(OFFSET(Assign!$B$106,MATCH($B13,Assign!$F$106:$F$128,0)-1,0),"") | D13: =IFERROR(OFFSET(Assign!$C$106,MATCH($B13,Assign!$F$106:$F$128,0)-1,0),"")
B14: 13 | C14: =IFERROR(OFFSET(Assign!$B$106,MATCH($B14,Assign!$F$106:$F$128,0)-1,0),"") | D14: =IFERROR(OFFSET(Assign!$C$106,MATCH($B14,Assign!$F$106:$F$128,0)-1,0),"")
B15: 14 | C15: =IFERROR(OFFSET(Assign!$B$106,MATCH($B15,Assign!$F$106:$F$128,0)-1,0),"") | D15: =IFERROR(OFFSET(Assign!$C$106,MATCH($B15,Assign!$F$106:$F$128,0)-1,0),"")
... B101: 100 | C101: =IFERROR(OFFSET(Assign!$B$106,MATCH($B101,Assign!$F$106:$F$128,0)-1,0),"") | D101: =IFERROR(OFFSET(Assign!$C$106,MATCH($B101,Assign!$F$106:$F$128,0)-1,0),"")

Sheet I2C
B1: Index | C1: Pin | D1: Name | E1: Connect to | F1: Type | G1: Function Description
B2: 1 | C2: =IFERROR(OFFSET(Assign!$B$130,MATCH($B2,Assign!$F$130:$F$140,0)-1,0),"") | D2: =IFERROR(OFFSET(Assign!$C$130,MATCH($B2,Assign!$F$130:$F$140,0)-1,0),"")
B3: 2 | C3: =IFERROR(OFFSET(Assign!$B$130,MATCH($B3,Assign!$F$130:$F$140,0)-1,0),"") | D3: =IFERROR(OFFSET(Assign!$C$130,MATCH($B3,Assign!$F$130:$F$140,0)-1,0),"")
B4: 3 | C4: =IFERROR(OFFSET(Assign!$B$130,MATCH($B4,Assign!$F$130:$F$140,0)-1,0),"") | D4: =IFERROR(OFFSET(Assign!$C$130,MATCH($B4,Assign!$F$130:$F$140,0)-1,0),"")
B5: 4 | C5: =IFERROR(OFFSET(Assign!$B$130,MATCH($B5,Assign!$F$130:$F$140,0)-1,0),"") | D5: =IFERROR(OFFSET(Assign!$C$130,MATCH($B5,Assign!$F$130:$F$140,0)-1,0),"")
B6: 5 | C6: =IFERROR(OFFSET(Assign!$B$130,MATCH($B6,Assign!$F$130:$F$140,0)-1,0),"") | D6: =IFERROR(OFFSET(Assign!$C$130,MATCH($B6,Assign!$F$130:$F$140,0)-1,0),"")
B7: 6 | C7: =IFERROR(OFFSET(Assign!$B$130,MATCH($B7,Assign!$F$130:$F$140,0)-1,0),"") | D7: =IFERROR(OFFSET(Assign!$C$130,MATCH($B7,Assign!$F$130:$F$140,0)-1,0),"")
B8: 7 | C8: =IFERROR(OFFSET(Assign!$B$130,MATCH($B8,Assign!$F$130:$F$140,0)-1,0),"") | D8: =IFERROR(OFFSET(Assign!$C$130,MATCH($B8,Assign!$F$130:$F$140,0)-1,0),"")
B9: 8 | C9: =IFERROR(OFFSET(Assign!$B$130,MATCH($B9,Assign!$F$130:$F$140,0)-1,0),"") | D9: =IFERROR(OFFSET(Assign!$C$130,MATCH($B9,Assign!$F$130:$F$140,0)-1,0),"")
B10: 9 | C10: =IFERROR(OFFSET(Assign!$B$130,MATCH($B10,Assign!$F$130:$F$140,0)-1,0),"") | D10: =IFERROR(OFFSET(Assign!$C$130,MATCH($B10,Assign!$F$130:$F$140,0)-1,0),"")
B11: 10 | C11: =IFERROR(OFFSET(Assign!$B$130,MATCH($B11,Assign!$F$130:$F$140,0)-1,0),"") | D11: =IFERROR(OFFSET(Assign!$C$130,MATCH($B11,Assign!$F$130:$F$140,0)-1,0),"")
B12: 11 | C12: =IFERROR(OFFSET(Assign!$B$130,MATCH($B12,Assign!$F$130:$F$140,0)-1,0),"") | D12: =IFERROR(OFFSET(Assign!$C$130,MATCH($B12,Assign!$F$130:$F$140,0)-1,0),"")
B13: 12 | C13: =IFERROR(OFFSET(Assign!$B$130,MATCH($B13,Assign!$F$130:$F$140,0)-1,0),"") | D13: =IFERROR(OFFSET(Assign!$C$130,MATCH($B13,Assign!$F$130:$F$140,0)-1,0),"")
... B101: 100 | C101: =IFERROR(OFFSET(Assign!$B$130,MATCH($B101,Assign!$F$130:$F$140,0)-1,0),"") | D101: =IFERROR(OFFSET(Assign!$C$130,MATCH($B101,Assign!$F$130:$F$140,0)-1,0),"")

Sheet PMBUS
B1: Index | C1: Pin | D1: Name | E1: Connect to | F1: Type | G1: Function Description
B2: 1 | C2: =IFERROR(OFFSET(Assign!$B$142,MATCH($B2,Assign!$F$142:$F$158,0)-1,0),"") | D2: =IFERROR(OFFSET(Assign!$C$142,MATCH($B2,Assign!$F$142:$F$158,0)-1,0),"")
B3: 2 | C3: =IFERROR(OFFSET(Assign!$B$142,MATCH($B3,Assign!$F$142:$F$158,0)-1,0),"") | D3: =IFERROR(OFFSET(Assign!$C$142,MATCH($B3,Assign!$F$142:$F$158,0)-1,0),"")
B4: 3 | C4: =IFERROR(OFFSET(Assign!$B$142,MATCH($B4,Assign!$F$142:$F$158,0)-1,0),"") | D4: =IFERROR(OFFSET(Assign!$C$142,MATCH($B4,Assign!$F$142:$F$158,0)-1,0),"")
B5: 4 | C5: =IFERROR(OFFSET(Assign!$B$142,MATCH($B5,Assign!$F$142:$F$158,0)-1,0),"") | D5: =IFERROR(OFFSET(Assign!$C$142,MATCH($B5,Assign!$F$142:$F$158,0)-1,0),"")
B6: 5 | C6: =IFERROR(OFFSET(Assign!$B$142,MATCH($B6,Assign!$F$142:$F$158,0)-1,0),"") | D6: =IFERROR(OFFSET(Assign!$C$142,MATCH($B6,Assign!$F$142:$F$158,0)-1,0),"")
B7: 6 | C7: =IFERROR(OFFSET(Assign!$B$142,MATCH($B7,Assign!$F$142:$F$158,0)-1,0),"") | D7: =IFERROR(OFFSET(Assign!$C$142,MATCH($B7,Assign!$F$142:$F$158,0)-1,0),"")
B8: 7 | C8: =IFERROR(OFFSET(Assign!$B$142,MATCH($B8,Assign!$F$142:$F$158,0)-1,0),"") | D8: =IFERROR(OFFSET(Assign!$C$142,MATCH($B8,Assign!$F$142:$F$158,0)-1,0),"")
B9: 8 | C9: =IFERROR(OFFSET(Assign!$B$142,MATCH($B9,Assign!$F$142:$F$158,0)-1,0),"") | D9: =IFERROR(OFFSET(Assign!$C$142,MATCH($B9,Assign!$F$142:$F$158,0)-1,0),"")
B10: 9 | C10: =IFERROR(OFFSET(Assign!$B$142,MATCH($B10,Assign!$F$142:$F$158,0)-1,0),"") | D10: =IFERROR(OFFSET(Assign!$C$142,MATCH($B10,Assign!$F$142:$F$158,0)-1,0),"")
B11: 10 | C11: =IFERROR(OFFSET(Assign!$B$142,MATCH($B11,Assign!$F$142:$F$158,0)-1,0),"") | D11: =IFERROR(OFFSET(Assign!$C$142,MATCH($B11,Assign!$F$142:$F$158,0)-1,0),"")
B12: 11 | C12: =IFERROR(OFFSET(Assign!$B$142,MATCH($B12,Assign!$F$142:$F$158,0)-1,0),"") | D12: =IFERROR(OFFSET(Assign!$C$142,MATCH($B12,Assign!$F$142:$F$158,0)-1,0),"")
B13: 12 | C13: =IFERROR(OFFSET(Assign!$B$142,MATCH($B13,Assign!$F$142:$F$158,0)-1,0),"") | D13: =IFERROR(OFFSET(Assign!$C$142,MATCH($B13,Assign!$F$142:$F$158,0)-1,0),"")
... B101: 100 | C101: =IFERROR(OFFSET(Assign!$B$142,MATCH($B101,Assign!$F$142:$F$158,0)-1,0),"") | D101: =IFERROR(OFFSET(Assign!$C$142,MATCH($B101,Assign!$F$142:$F$158,0)-1,0),"")

Sheet CAN
B1: Index | C1: Pin | D1: Name | E1: Connect to | F1: Type | G1: Function Description
B2: 1 | C2: =IFERROR(OFFSET(Assign!$B$160,MATCH($B2,Assign!$F$160:$F$179,0)-1,0),"") | D2: =IFERROR(OFFSET(Assign!$C$160,MATCH($B2,Assign!$F$160:$F$179,0)-1,0),"")
B3: 2 | C3: =IFERROR(OFFSET(Assign!$B$160,MATCH($B3,Assign!$F$160:$F$179,0)-1,0),"") | D3: =IFERROR(OFFSET(Assign!$C$160,MATCH($B3,Assign!$F$160:$F$179,0)-1,0),"")
B4: 3 | C4: =IFERROR(OFFSET(Assign!$B$160,MATCH($B4,Assign!$F$160:$F$179,0)-1,0),"") | D4: =IFERROR(OFFSET(Assign!$C$160,MATCH($B4,Assign!$F$160:$F$179,0)-1,0),"")
B5: 4 | C5: =IFERROR(OFFSET(Assign!$B$160,MATCH($B5,Assign!$F$160:$F$179,0)-1,0),"") | D5: =IFERROR(OFFSET(Assign!$C$160,MATCH($B5,Assign!$F$160:$F$179,0)-1,0),"")
B6: 5 | C6: =IFERROR(OFFSET(Assign!$B$160,MATCH($B6,Assign!$F$160:$F$179,0)-1,0),"") | D6: =IFERROR(OFFSET(Assign!$C$160,MATCH($B6,Assign!$F$160:$F$179,0)-1,0),"")
B7: 6 | C7: =IFERROR(OFFSET(Assign!$B$160,MATCH($B7,Assign!$F$160:$F$179,0)-1,0),"") | D7: =IFERROR(OFFSET(Assign!$C$160,MATCH($B7,Assign!$F$160:$F$179,0)-1,0),"")
B8: 7 | C8: =IFERROR(OFFSET(Assign!$B$160,MATCH($B8,Assign!$F$160:$F$179,0)-1,0),"") | D8: =IFERROR(OFFSET(Assign!$C$160,MATCH($B8,Assign!$F$160:$F$179,0)-1,0),"")
B9: 8 | C9: =IFERROR(OFFSET(Assign!$B$160,MATCH($B9,Assign!$F$160:$F$179,0)-1,0),"") | D9: =IFERROR(OFFSET(Assign!$C$160,MATCH($B9,Assign!$F$160:$F$179,0)-1,0),"")
B10: 9 | C10: =IFERROR(OFFSET(Assign!$B$160,MATCH($B10,Assign!$F$160:$F$179,0)-1,0),"") | D10: =IFERROR(OFFSET(Assign!$C$160,MATCH($B10,Assign!$F$160:$F$179,0)-1,0),"")
B11: 10 | C11: =IFERROR(OFFSET(Assign!$B$160,MATCH($B11,Assign!$F$160:$F$179,0)-1,0),"") | D11: =IFERROR(OFFSET(Assign!$C$160,MATCH($B11,Assign!$F$160:$F$179,0)-1,0),"")
B12: 11 | C12: =IFERROR(OFFSET(Assign!$B$160,MATCH($B12,Assign!$F$160:$F$179,0)-1,0),"") | D12: =IFERROR(OFFSET(Assign!$C$160,MATCH($B12,Assign!$F$160:$F$179,0)-1,0),"")
B13: 12 | C13: =IFERROR(OFFSET(Assign!$B$160,MATCH($B13,Assign!$F$160:$F$179,0)-1,0),"") | D13: =IFERROR(OFFSET(Assign!$C$160,MATCH($B13,Assign!$F$160:$F$179,0)-1,0),"")
... B101: 100 | C101: =IFERROR(OFFSET(Assign!$B$160,MATCH($B101,Assign!$F$160:$F$179,0)-1,0),"") | D101: =IFERROR(OFFSET(Assign!$C$160,MATCH($B101,Assign!$F$160:$F$179,0)-1,0),"")

Sheet SPI
B1: Index | C1: Pin | D1: Name | E1: Connect to | F1: Type | G1: Function Description
B2: 1 | C2: =IFERROR(OFFSET(Assign!$B$181,MATCH($B2,Assign!$F$181:$F$208,0)-1,0),"") | D2: =IFERROR(OFFSET(Assign!$C$181,MATCH($B2,Assign!$F$181:$F$208,0)-1,0),"")
B3: 2 | C3: =IFERROR(OFFSET(Assign!$B$181,MATCH($B3,Assign!$F$181:$F$208,0)-1,0),"") | D3: =IFERROR(OFFSET(Assign!$C$181,MATCH($B3,Assign!$F$181:$F$208,0)-1,0),"")
B4: 3 | C4: =IFERROR(OFFSET(Assign!$B$181,MATCH($B4,Assign!$F$181:$F$208,0)-1,0),"") | D4: =IFERROR(OFFSET(Assign!$C$181,MATCH($B4,Assign!$F$181:$F$208,0)-1,0),"")
B5: 4 | C5: =IFERROR(OFFSET(Assign!$B$181,MATCH($B5,Assign!$F$181:$F$208,0)-1,0),"") | D5: =IFERROR(OFFSET(Assign!$C$181,MATCH($B5,Assign!$F$181:$F$208,0)-1,0),"")
B6: 5 | C6: =IFERROR(OFFSET(Assign!$B$181,MATCH($B6,Assign!$F$181:$F$208,0)-1,0),"") | D6: =IFERROR(OFFSET(Assign!$C$181,MATCH($B6,Assign!$F$181:$F$208,0)-1,0),"")
B7: 6 | C7: =IFERROR(OFFSET(Assign!$B$181,MATCH($B7,Assign!$F$181:$F$208,0)-1,0),"") | D7: =IFERROR(OFFSET(Assign!$C$181,MATCH($B7,Assign!$F$181:$F$208,0)-1,0),"")
B8: 7 | C8: =IFERROR(OFFSET(Assign!$B$181,MATCH($B8,Assign!$F$181:$F$208,0)-1,0),"") | D8: =IFERROR(OFFSET(Assign!$C$181,MATCH($B8,Assign!$F$181:$F$208,0)-1,0),"")
B9: 8 | C9: =IFERROR(OFFSET(Assign!$B$181,MATCH($B9,Assign!$F$181:$F$208,0)-1,0),"") | D9: =IFERROR(OFFSET(Assign!$C$181,MATCH($B9,Assign!$F$181:$F$208,0)-1,0),"")
B10: 9 | C10: =IFERROR(OFFSET(Assign!$B$181,MATCH($B10,Assign!$F$181:$F$208,0)-1,0),"") | D10: =IFERROR(OFFSET(Assign!$C$181,MATCH($B10,Assign!$F$181:$F$208,0)-1,0),"")
B11: 10 | C11: =IFERROR(OFFSET(Assign!$B$181,MATCH($B11,Assign!$F$181:$F$208,0)-1,0),"") | D11: =IFERROR(OFFSET(Assign!$C$181,MATCH($B11,Assign!$F$181:$F$208,0)-1,0),"")
B12: 11 | C12: =IFERROR(OFFSET(Assign!$B$181,MATCH($B12,Assign!$F$181:$F$208,0)-1,0),"") | D12: =IFERROR(OFFSET(Assign!$C$181,MATCH($B12,Assign!$F$181:$F$208,0)-1,0),"")
B13: 12 | C13: =IFERROR(OFFSET(Assign!$B$181,MATCH($B13,Assign!$F$181:$F$208,0)-1,0),"") | D13: =IFERROR(OFFSET(Assign!$C$181,MATCH($B13,Assign!$F$181:$F$208,0)-1,0),"")
... B101: 100 | C101: =IFERROR(OFFSET(Assign!$B$181,MATCH($B101,Assign!$F$181:$F$208,0)-1,0),"") | D101: =IFERROR(OFFSET(Assign!$C$181,MATCH($B101,Assign!$F$181:$F$208,0)-1,0),"")

Sheet GPIO
B1: Index | C1: Pin | D1: Name | E1: Connect to | F1: Type | G1: Function Description
B2: 1 | C2: =IFERROR(OFFSET(Assign!$B$210,MATCH($B2,Assign!$F$210:$F$249,0)-1,0),"") -> 50 | D2: =IFERROR(OFFSET(Assign!$C$210,MATCH($B2,Assign!$F$210:$F$249,0)-1,0),"") -> GPIO13/ EPWM7_B/ CANB_RX/ EQEP1_INDEX/ SCIB_RX/ PMBUSA_ALERT/ FSIRXA_CLK | E2: GPIO_VAC_B_OK_P | F2: DO | G2: Input_OK signal
B3: 2 | C3: =IFERROR(OFFSET(Assign!$B$210,MATCH($B3,Assign!$F$210:$F$249,0)-1,0),"") -> 51 | D3: =IFERROR(OFFSET(Assign!$C$210,MATCH($B3,Assign!$F$210:$F$249,0)-1,0),"") -> GPIO12/ EPWM7_A/ CANB_TX/ EQEP1_STROBE/ SCIB_TX/ PMBUSA_CTL/ FSIRXA_D0 | E3: GPIO_PSKILL_P | F3: DI | G3: PSKILL signal
B4: 3 | C4: =IFERROR(OFFSET(Assign!$B$210,MATCH($B4,Assign!$F$210:$F$249,0)-1,0),"") -> 53 | D4: =IFERROR(OFFSET(Assign!$C$210,MATCH($B4,Assign!$F$210:$F$249,0)-1,0),"") -> GPIO33/ I2CA_SCL/ SPIB_STE/ OUTPUTXBAR4/ LINA_RX/ SD1_C3/ FSIRXA_CLK/ CANA_RX | E4: GPIO_DEBUG | F4: DO | G4: Heart beat LED / debug
B5: 4 | C5: =IFERROR(OFFSET(Assign!$B$210,MATCH($B5,Assign!$F$210:$F$249,0)-1,0),"") -> 57 | D5: =IFERROR(OFFSET(Assign!$C$210,MATCH($B5,Assign!$F$210:$F$249,0)-1,0),"") -> GPIO25/ OUTPUTXBAR2/ EQEP2_B/ SPIB_SOMI/ SD1_C1/ FSITXA_D1/ PMBUSA_SDA/ SCIA_RX | E5: GPIO_EN_PFC | F5: DO | G5: PFC drive enable signal
B6: 5 | C6: =IFERROR(OFFSET(Assign!$B$210,MATCH($B6,Assign!$F$210:$F$249,0)-1,0),"") -> 58 | D6: =IFERROR(OFFSET(Assign!$C$210,MATCH($B6,Assign!$F$210:$F$249,0)-1,0),"") -> GPIO26/ OUTPUTXBAR3/ EQEP2_INDEX/ SPIB_CLK/ SD1_D2/ FSITXA_D0/ PMBUSA_CTL/ I2CA_SDA | E6: GPIO_EN_BB | F6: DO | G6: Baby Boost enable signal
B7: 6 | C7: =IFERROR(OFFSET(Assign!$B$210,MATCH($B7,Assign!$F$210:$F$249,0)-1,0),"") -> 90 | D7: =IFERROR(OFFSET(Assign!$C$210,MATCH($B7,Assign!$F$210:$F$249,0)-1,0),"") -> GPIO9/ EPWM5_B/ SCIB_TX/ OUTPUTXBAR6/ EQEP1_INDEX/ SCIA_RX/ SPIA_CLK/ FSITXA_D0 | E7: GPIO_SRVC_LED | F7: DO | G7: LED control signal
B8: 7 | C8: =IFERROR(OFFSET(Assign!$B$210,MATCH($B8,Assign!$F$210:$F$249,0)-1,0),"") -> 91 | D8: =IFERROR(OFFSET(Assign!$C$210,MATCH($B8,Assign!$F$210:$F$249,0)-1,0),"") -> GPIO39/ CANB_RX/ FSIRXA_CLK | E8: GPIO_O/P_LED | F8: DO | G8: LED control signal
B9: 8 | C9: =IFERROR(OFFSET(Assign!$B$210,MATCH($B9,Assign!$F$210:$F$249,0)-1,0),"") -> 92 | D9: =IFERROR(OFFSET(Assign!$C$210,MATCH($B9,Assign!$F$210:$F$249,0)-1,0),"") -> GPIO59/ OUTPUTXBAR2/ SPIB_STE/ SD1_C4/ LINA_RX/ CANB_RX/ EQEP1_INDEX | E9: GPIO_I/P_LED_Y | F9: DO | G9: LED control signal
B10: 9 | C10: =IFERROR(OFFSET(Assign!$B$210,MATCH($B10,Assign!$F$210:$F$249,0)-1,0),"") -> 94 | D10: =IFERROR(OFFSET(Assign!$C$210,MATCH($B10,Assign!$F$210:$F$249,0)-1,0),"") -> GPIO34/ OUTPUTXBAR1/ PMBUSA_SDA | E10: GPIO_I/P_LED_G | F10: DO | G10: LED control signal
B11: 10 | C11: =IFERROR(OFFSET(Assign!$B$210,MATCH($B11,Assign!$F$210:$F$249,0)-1,0),"") -> 95 | D11: =IFERROR(OFFSET(Assign!$C$210,MATCH($B11,Assign!$F$210:$F$249,0)-1,0),"") -> GPIO15/ EPWM8_B/ SCIB_RX/ OUTPUTXBAR4/ PMBUSA_SCL/ SPIB_STE/ EQEP2_B | E11: GPIO_FAN2_TACH | F11: CAP | G11: Capture1 for Fan2 speed detection
B12: 11 | C12: =IFERROR(OFFSET(Assign!$B$210,MATCH($B12,Assign!$F$210:$F$249,0)-1,0),"") -> 96 | D12: =IFERROR(OFFSET(Assign!$C$210,MATCH($B12,Assign!$F$210:$F$249,0)-1,0),"") -> GPIO14/ EPWM8_A/ SCIB_TX/ OUTPUTXBAR3/ PMBUSA_SDA/ SPIB_CLK/ EQEP2_A | E12: GPIO_FAN1_TACH | F12: CAP | G12: Capture2 for Fan1 speed detection
B13: 12 | C13: =IFERROR(OFFSET(Assign!$B$210,MATCH($B13,Assign!$F$210:$F$249,0)-1,0),"") -> 99 | D13: =IFERROR(OFFSET(Assign!$C$210,MATCH($B13,Assign!$F$210:$F$249,0)-1,0),"") -> GPIO31/ CANA_TX/ SPIB_SOMI/ OUTPUTXBAR8/ EQEP1_INDEX/ SD1_C4/ FSIRXA_D1 | E13: GPIO_RELAY_ON | F13: DO | G13: Relay control signal
B14: 13 | C14: =IFERROR(OFFSET(Assign!$B$210,MATCH($B14,Assign!$F$210:$F$249,0)-1,0),"") | D14: =IFERROR(OFFSET(Assign!$C$210,MATCH($B14,Assign!$F$210:$F$249,0)-1,0),"")
B15: 14 | C15: =IFERROR(OFFSET(Assign!$B$210,MATCH($B15,Assign!$F$210:$F$249,0)-1,0),"") | D15: =IFERROR(OFFSET(Assign!$C$210,MATCH($B15,Assign!$F$210:$F$249,0)-1,0),"")
B16: 15 | C16: =IFERROR(OFFSET(Assign!$B$210,MATCH($B16,Assign!$F$210:$F$249,0)-1,0),"") | D16: =IFERROR(OFFSET(Assign!$C$210,MATCH($B16,Assign!$F$210:$F$249,0)-1,0),"")
B17: 16 | C17: =IFERROR(OFFSET(Assign!$B$210,MATCH($B17,Assign!$F$210:$F$249,0)-1,0),"") | D17: =IFERROR(OFFSET(Assign!$C$210,MATCH($B17,Assign!$F$210:$F$249,0)-1,0),"")
B18: 17 | C18: =IFERROR(OFFSET(Assign!$B$210,MATCH($B18,Assign!$F$210:$F$249,0)-1,0),"") | D18: =IFERROR(OFFSET(Assign!$C$210,MATCH($B18,Assign!$F$210:$F$249,0)-1,0),"")
B19: 18 | C19: =IFERROR(OFFSET(Assign!$B$210,MATCH($B19,Assign!$F$210:$F$249,0)-1,0),"") | D19: =IFERROR(OFFSET(Assign!$C$210,MATCH($B19,Assign!$F$210:$F$249,0)-1,0),"")
B20: 19 | C20: =IFERROR(OFFSET(Assign!$B$210,MATCH($B20,Assign!$F$210:$F$249,0)-1,0),"") | D20: =IFERROR(OFFSET(Assign!$C$210,MATCH($B20,Assign!$F$210:$F$249,0)-1,0),"")
B21: 20 | C21: =IFERROR(OFFSET(Assign!$B$210,MATCH($B21,Assign!$F$210:$F$249,0)-1,0),"") | D21: =IFERROR(OFFSET(Assign!$C$210,MATCH($B21,Assign!$F$210:$F$249,0)-1,0),"")
B22: 21 | C22: =IFERROR(OFFSET(Assign!$B$210,MATCH($B22,Assign!$F$210:$F$249,0)-1,0),"") | D22: =IFERROR(OFFSET(Assign!$C$210,MATCH($B22,Assign!$F$210:$F$249,0)-1,0),"")
B23: 22 | C23: =IFERROR(OFFSET(Assign!$B$210,MATCH($B23,Assign!$F$210:$F$249,0)-1,0),"") | D23: =IFERROR(OFFSET(Assign!$C$210,MATCH($B23,Assign!$F$210:$F$249,0)-1,0),"")
B24: 23 | C24: =IFERROR(OFFSET(Assign!$B$210,MATCH($B24,Assign!$F$210:$F$249,0)-1,0),"") | D24: =IFERROR(OFFSET(Assign!$C$210,MATCH($B24,Assign!$F$210:$F$249,0)-1,0),"")
B25: 24 | C25: =IFERROR(OFFSET(Assign!$B$210,MATCH($B25,Assign!$F$210:$F$249,0)-1,0),"") | D25: =IFERROR(OFFSET(Assign!$C$210,MATCH($B25,Assign!$F$210:$F$249,0)-1,0),"")
... B101: 100 | C101: =IFERROR(OFFSET(Assign!$B$210,MATCH($B101,Assign!$F$210:$F$249,0)-1,0),"") | D101: =IFERROR(OFFSET(Assign!$C$210,MATCH($B101,Assign!$F$210:$F$249,0)-1,0),"")
